Workbook

Sheet PAINEL
A1: PAINEL – MAPA COMPARATIVO DE FALHAS, ERROS E OUTROS DO MQT
A2: Pavilhão gimnodesportivo escolar · MQT_CUSTO-VENDA.XLS · 14 capítulos, 833 artigos · todos os valores por fórmula a partir das restantes folhas
A3: PARECER: NÃO VALIDAR o MQT na versão atual – corrigir os achados CRÍTICOS e ALTOS e voltar a submeter.
A4: INDICADORES
A5: Achados ativos (verificados) | C5: =COUNTIFS('MAPA COMPARATIVO'!$V$5:$V$206,"<>REJEITADO") -> 202
A6: dos quais CRÍTICOS | C6: =COUNTIFS('MAPA COMPARATIVO'!$G$5:$G$206,"CRÍTICA",'MAPA COMPARATIVO'!$V$5:$V$206,"<>REJEITADO") -> 1
A7: dos quais ALTOS | C7: =COUNTIFS('MAPA COMPARATIVO'!$G$5:$G$206,"ALTA",'MAPA COMPARATIVO'!$V$5:$V$206,"<>REJEITADO") -> 34
A8: Rejeitados na verificação (fora do mapa) | C8: =COUNTA('REJEITADOS NA VERIFICAÇÃO'!A5:A500) -> 9
A9: Custo MQT (€) | C9: ='CUSTO vs VENDA'!C21 -> 4499642.1
A10: Venda MQT (€) | C10: ='CUSTO vs VENDA'!D21 -> 4499630
A11: Venda − Custo (€) | C11: ='CUSTO vs VENDA'!E21 -> -12.12
A12: Impacto líquido cenário A (€) | C12: =SUMIFS('MAPA COMPARATIVO'!$O$5:$O$206,'MAPA COMPARATIVO'!$V$5:$V$206,"<>REJEITADO") -> 115594.89
A13: Impacto líquido cenário B (€) | C13: =SUMIFS('MAPA COMPARATIVO'!$P$5:$P$206,'MAPA COMPARATIVO'!$V$5:$V$206,"<>REJEITADO") -> 399725.14
A14: Custo corrigido cenário A (€) | C14: ='CUSTO vs VENDA'!I21 -> 4615237
A15: Custo corrigido cenário B (€) | C15: ='CUSTO vs VENDA'!J21 -> 4899367.2
A16: Venda proposta com K – cenário A (€) | C16: ='CUSTO vs VENDA'!K21 -> 5538284.4
A17: Venda proposta com K – cenário B (€) | C17: ='CUSTO vs VENDA'!L21 -> 5879240.7
A18: K usado (editar em CUSTO vs VENDA!C3) | C18: ='CUSTO vs VENDA'!C3 -> 1.2
A20: COMPARAÇÃO POR TIPO × GRAVIDADE
A21: Tipo | C21: CRÍTICA | D21: ALTA | E21: MÉDIA | F21: BAIXA | G21: TOTAL | H21: Impacto A – mín (€) | I21: Impacto B – máx (€)
A22: ERRO | C22: =COUNTIFS('MAPA COMPARATIVO'!$F$5:$F$206,$A22,'MAPA COMPARATIVO'!$G$5:$G$206,"CRÍTICA",'MAPA COMPARATIVO'!$V$5:$V$206,"<>REJEITADO") -> 1 | D22: =COUNTIFS('MAPA COMPARATIVO'!$F$5:$F$206,$A22,'MAPA COMPARATIVO'!$G$5:$G$206,"ALTA",'MAPA COMPARATIVO'!$V$5:$V$206,"<>REJEITADO") -> 3 | E22: =COUNTIFS('MAPA COMPARATIVO'!$F$5:$F$206,$A22,'MAPA COMPARATIVO'!$G$5:$G$206,"MÉDIA",'MAPA COMPARATIVO'!$V$5:$V$206,"<>REJEITADO") -> 4 | F22: =COUNTIFS('MAPA COMPARATIVO'!$F$5:$F$206,$A22,'MAPA COMPARATIVO'!$G$5:$G$206,"BAIXA",'MAPA COMPARATIVO'!$V$5:$V$206,"<>REJEITADO") -> 14 | G22: =SUM(C22:F22) -> 22 | H22: =SUMIFS('MAPA COMPARATIVO'!$O$5:$O$206,'MAPA COMPARATIVO'!$F$5:$F$206,$A22,'MAPA COMPARATIVO'!$V$5:$V$206,"<>REJEITADO") -> -10430.43 | I22: =SUMIFS('MAPA COMPARATIVO'!$P$5:$P$206,'MAPA COMPARATIVO'!$F$5:$F$206,$A22,'MAPA COMPARATIVO'!$V$5:$V$206,"<>REJEITADO") -> -20500.23
A23: FALHA/OMISSÃO | C23: =COUNTIFS('MAPA COMPARATIVO'!$F$5:$F$206,$A23,'MAPA COMPARATIVO'!$G$5:$G$206,"CRÍTICA",'MAPA COMPARATIVO'!$V$5:$V$206,"<>REJEITADO") -> 0 | D23: =COUNTIFS('MAPA COMPARATIVO'!$F$5:$F$206,$A23,'MAPA COMPARATIVO'!$G$5:$G$206,"ALTA",'MAPA COMPARATIVO'!$V$5:$V$206,"<>REJEITADO") -> 12 | E23: =COUNTIFS('MAPA COMPARATIVO'!$F$5:$F$206,$A23,'MAPA COMPARATIVO'!$G$5:$G$206,"MÉDIA",'MAPA COMPARATIVO'!$V$5:$V$206,"<>REJEITADO") -> 15 | F23: =COUNTIFS('MAPA COMPARATIVO'!$F$5:$F$206,$A23,'MAPA COMPARATIVO'!$G$5:$G$206,"BAIXA",'MAPA COMPARATIVO'!$V$5:$V$206,"<>REJEITADO") -> 4 | G23: =SUM(C23:F23) -> 31 | H23: =SUMIFS('MAPA COMPARATIVO'!$O$5:$O$206,'MAPA COMPARATIVO'!$F$5:$F$206,$A23,'MAPA COMPARATIVO'!$V$5:$V$206,"<>REJEITADO") -> 83480 | I23: =SUMIFS('MAPA COMPARATIVO'!$P$5:$P$206,'MAPA COMPARATIVO'!$F$5:$F$206,$A23,'MAPA COMPARATIVO'!$V$5:$V$206,"<>REJEITADO") -> 327087.24
A24: DUPLICAÇÃO | C24: =COUNTIFS('MAPA COMPARATIVO'!$F$5:$F$206,$A24,'MAPA COMPARATIVO'!$G$5:$G$206,"CRÍTICA",'MAPA COMPARATIVO'!$V$5:$V$206,"<>REJEITADO") -> 0 | D24: =COUNTIFS('MAPA COMPARATIVO'!$F$5:$F$206,$A24,'MAPA COMPARATIVO'!$G$5:$G$206,"ALTA",'MAPA COMPARATIVO'!$V$5:$V$206,"<>REJEITADO") -> 5 | E24: =COUNTIFS('MAPA COMPARATIVO'!$F$5:$F$206,$A24,'MAPA COMPARATIVO'!$G$5:$G$206,"MÉDIA",'MAPA COMPARATIVO'!$V$5:$V$206,"<>REJEITADO") -> 3 | F24: =COUNTIFS('MAPA COMPARATIVO'!$F$5:$F$206,$A24,'MAPA COMPARATIVO'!$G$5:$G$206,"BAIXA",'MAPA COMPARATIVO'!$V$5:$V$206,"<>REJEITADO") -> 9 | G24: =SUM(C24:F24) -> 17 | H24: =SUMIFS('MAPA COMPARATIVO'!$O$5:$O$206,'MAPA COMPARATIVO'!$F$5:$F$206,$A24,'MAPA COMPARATIVO'!$V$5:$V$206,"<>REJEITADO") -> -25714.01 | I24: =SUMIFS('MAPA COMPARATIVO'!$P$5:$P$206,'MAPA COMPARATIVO'!$F$5:$F$206,$A24,'MAPA COMPARATIVO'!$V$5:$V$206,"<>REJEITADO") -> -58092.59
A25: PREÇO BAIXO | C25: =COUNTIFS('MAPA COMPARATIVO'!$F$5:$F$206,$A25,'MAPA COMPARATIVO'!$G$5:$G$206,"CRÍTICA",'MAPA COMPARATIVO'!$V$5:$V$206,"<>REJEITADO") -> 0 | D25: =COUNTIFS('MAPA COMPARATIVO'!$F$5:$F$206,$A25,'MAPA COMPARATIVO'!$G$5:$G$206,"ALTA",'MAPA COMPARATIVO'!$V$5:$V$206,"<>REJEITADO") -> 6 | E25: =COUNTIFS('MAPA COMPARATIVO'!$F$5:$F$206,$A25,'MAPA COMPARATIVO'!$G$5:$G$206,"MÉDIA",'MAPA COMPARATIVO'!$V$5:$V$206,"<>REJEITADO") -> 20 | F25: =COUNTIFS('MAPA COMPARATIVO'!$F$5:$F$206,$A25,'MAPA COMPARATIVO'!$G$5:$G$206,"BAIXA",'MAPA COMPARATIVO'!$V$5:$V$206,"<>REJEITADO") -> 13 | G25: =SUM(C25:F25) -> 39 | H25: =SUMIFS('MAPA COMPARATIVO'!$O$5:$O$206,'MAPA COMPARATIVO'!$F$5:$F$206,$A25,'MAPA COMPARATIVO'!$V$5:$V$206,"<>REJEITADO") -> 106965.34 | I25: =SUMIFS('MAPA COMPARATIVO'!$P$5:$P$206,'MAPA COMPARATIVO'!$F$5:$F$206,$A25,'MAPA COMPARATIVO'!$V$5:$V$206,"<>REJEITADO") -> 262194.09
A26: PREÇO ALTO | C26: =COUNTIFS('MAPA COMPARATIVO'!$F$5:$F$206,$A26,'MAPA COMPARATIVO'!$G$5:$G$206,"CRÍTICA",'MAPA COMPARATIVO'!$V$5:$V$206,"<>REJEITADO") -> 0 | D26: =COUNTIFS('MAPA COMPARATIVO'!$F$5:$F$206,$A26,'MAPA COMPARATIVO'!$G$5:$G$206,"ALTA",'MAPA COMPARATIVO'!$V$5:$V$206,"<>REJEITADO") -> 0 | E26: =COUNTIFS('MAPA COMPARATIVO'!$F$5:$F$206,$A26,'MAPA COMPARATIVO'!$G$5:$G$206,"MÉDIA",'MAPA COMPARATIVO'!$V$5:$V$206,"<>REJEITADO") -> 1 | F26: =COUNTIFS('MAPA COMPARATIVO'!$F$5:$F$206,$A26,'MAPA COMPARATIVO'!$G$5:$G$206,"BAIXA",'MAPA COMPARATIVO'!$V$5:$V$206,"<>REJEITADO") -> 1 | G26: =SUM(C26:F26) -> 2 | H26: =SUMIFS('MAPA COMPARATIVO'!$O$5:$O$206,'MAPA COMPARATIVO'!$F$5:$F$206,$A26,'MAPA COMPARATIVO'!$V$5:$V$206,"<>REJEITADO") -> -3478.58 | I26: =SUMIFS('MAPA COMPARATIVO'!$P$5:$P$206,'MAPA COMPARATIVO'!$F$5:$F$206,$A26,'MAPA COMPARATIVO'!$V$5:$V$206,"<>REJEITADO") -> -5037.68
A27: INCOERÊNCIA | C27: =COUNTIFS('MAPA COMPARATIVO'!$F$5:$F$206,$A27,'MAPA COMPARATIVO'!$G$5:$G$206,"CRÍTICA",'MAPA COMPARATIVO'!$V$5:$V$206,"<>REJEITADO") -> 0 | D27: =COUNTIFS('MAPA COMPARATIVO'!$F$5:$F$206,$A27,'MAPA COMPARATIVO'!$G$5:$G$206,"ALTA",'MAPA COMPARATIVO'!$V$5:$V$206,"<>REJEITADO") -> 2 | E27: =COUNTIFS('MAPA COMPARATIVO'!$F$5:$F$206,$A27,'MAPA COMPARATIVO'!$G$5:$G$206,"MÉDIA",'MAPA COMPARATIVO'!$V$5:$V$206,"<>REJEITADO") -> 9 | F27: =COUNTIFS('MAPA COMPARATIVO'!$F$5:$F$206,$A27,'MAPA COMPARATIVO'!$G$5:$G$206,"BAIXA",'MAPA COMPARATIVO'!$V$5:$V$206,"<>REJEITADO") -> 13 | G27: =SUM(C27:F27) -> 24 | H27: =SUMIFS('MAPA COMPARATIVO'!$O$5:$O$206,'MAPA COMPARATIVO'!$F$5:$F$206,$A27,'MAPA COMPARATIVO'!$V$5:$V$206,"<>REJEITADO") -> -38297.49 | I27: =SUMIFS('MAPA COMPARATIVO'!$P$5:$P$206,'MAPA COMPARATIVO'!$F$5:$F$206,$A27,'MAPA COMPARATIVO'!$V$5:$V$206,"<>REJEITADO") -> -35930.15
A28: DESCRIÇÃO | C28: =COUNTIFS('MAPA COMPARATIVO'!$F$5:$F$206,$A28,'MAPA COMPARATIVO'!$G$5:$G$206,"CRÍTICA",'MAPA COMPARATIVO'!$V$5:$V$206,"<>REJEITADO") -> 0 | D28: =COUNTIFS('MAPA COMPARATIVO'!$F$5:$F$206,$A28,'MAPA COMPARATIVO'!$G$5:$G$206,"ALTA",'MAPA COMPARATIVO'!$V$5:$V$206,"<>REJEITADO") -> 3 | E28: =COUNTIFS('MAPA COMPARATIVO'!$F$5:$F$206,$A28,'MAPA COMPARATIVO'!$G$5:$G$206,"MÉDIA",'MAPA COMPARATIVO'!$V$5:$V$206,"<>REJEITADO") -> 9 | F28: =COUNTIFS('MAPA COMPARATIVO'!$F$5:$F$206,$A28,'MAPA COMPARATIVO'!$G$5:$G$206,"BAIXA",'MAPA COMPARATIVO'!$V$5:$V$206,"<>REJEITADO") -> 11 | G28: =SUM(C28:F28) -> 23 | H28: =SUMIFS('MAPA COMPARATIVO'!$O$5:$O$206,'MAPA COMPARATIVO'!$F$5:$F$206,$A28,'MAPA COMPARATIVO'!$V$5:$V$206,"<>REJEITADO") -> -172.1 | I28: =SUMIFS('MAPA COMPARATIVO'!$P$5:$P$206,'MAPA COMPARATIVO'!$F$5:$F$206,$A28,'MAPA COMPARATIVO'!$V$5:$V$206,"<>REJEITADO") -> -3452.71
A29: NORMA | C29: =COUNTIFS('MAPA COMPARATIVO'!$F$5:$F$206,$A29,'MAPA COMPARATIVO'!$G$5:$G$206,"CRÍTICA",'MAPA COMPARATIVO'!$V$5:$V$206,"<>REJEITADO") -> 0 | D29: =COUNTIFS('MAPA COMPARATIVO'!$F$5:$F$206,$A29,'MAPA COMPARATIVO'!$G$5:$G$206,"ALTA",'MAPA COMPARATIVO'!$V$5:$V$206,"<>REJEITADO") -> 2 | E29: =COUNTIFS('MAPA COMPARATIVO'!$F$5:$F$206,$A29,'MAPA COMPARATIVO'!$G$5:$G$206,"MÉDIA",'MAPA COMPARATIVO'!$V$5:$V$206,"<>REJEITADO") -> 5 | F29: =COUNTIFS('MAPA COMPARATIVO'!$F$5:$F$206,$A29,'MAPA COMPARATIVO'!$G$5:$G$206,"BAIXA",'MAPA COMPARATIVO'!$V$5:$V$206,"<>REJEITADO") -> 3 | G29: =SUM(C29:F29) -> 10 | H29: =SUMIFS('MAPA COMPARATIVO'!$O$5:$O$206,'MAPA COMPARATIVO'!$F$5:$F$206,$A29,'MAPA COMPARATIVO'!$V$5:$V$206,"<>REJEITADO") -> 3700 | I29: =SUMIFS('MAPA COMPARATIVO'!$P$5:$P$206,'MAPA COMPARATIVO'!$F$5:$F$206,$A29,'MAPA COMPARATIVO'!$V$5:$V$206,"<>REJEITADO") -> -62784.92
A30: INCOMPATIBILIDADE | C30: =COUNTIFS('MAPA COMPARATIVO'!$F$5:$F$206,$A30,'MAPA COMPARATIVO'!$G$5:$G$206,"CRÍTICA",'MAPA COMPARATIVO'!$V$5:$V$206,"<>REJEITADO") -> 0 | D30: =COUNTIFS('MAPA COMPARATIVO'!$F$5:$F$206,$A30,'MAPA COMPARATIVO'!$G$5:$G$206,"ALTA",'MAPA COMPARATIVO'!$V$5:$V$206,"<>REJEITADO") -> 0 | E30: =COUNTIFS('MAPA COMPARATIVO'!$F$5:$F$206,$A30,'MAPA COMPARATIVO'!$G$5:$G$206,"MÉDIA",'MAPA COMPARATIVO'!$V$5:$V$206,"<>REJEITADO") -> 1 | F30: =COUNTIFS('MAPA COMPARATIVO'!$F$5:$F$206,$A30,'MAPA COMPARATIVO'!$G$5:$G$206,"BAIXA",'MAPA COMPARATIVO'!$V$5:$V$206,"<>REJEITADO") -> 0 | G30: =SUM(C30:F30) -> 1 | H30: =SUMIFS('MAPA COMPARATIVO'!$O$5:$O$206,'MAPA COMPARATIVO'!$F$5:$F$206,$A30,'MAPA COMPARATIVO'!$V$5:$V$206,"<>REJEITADO") -> 0 | I30: =SUMIFS('MAPA COMPARATIVO'!$P$5:$P$206,'MAPA COMPARATIVO'!$F$5:$F$206,$A30,'MAPA COMPARATIVO'!$V$5:$V$206,"<>REJEITADO") -> 5066.5
A31: EXTRA/FORA DE ÂMBITO | C31: =COUNTIFS('MAPA COMPARATIVO'!$F$5:$F$206,$A31,'MAPA COMPARATIVO'!$G$5:$G$206,"CRÍTICA",'MAPA COMPARATIVO'!$V$5:$V$206,"<>REJEITADO") -> 0 | D31: =COUNTIFS('MAPA COMPARATIVO'!$F$5:$F$206,$A31,'MAPA COMPARATIVO'!$G$5:$G$206,"ALTA",'MAPA COMPARATIVO'!$V$5:$V$206,"<>REJEITADO") -> 0 | E31: =COUNTIFS('MAPA COMPARATIVO'!$F$5:$F$206,$A31,'MAPA COMPARATIVO'!$G$5:$G$206,"MÉDIA",'MAPA COMPARATIVO'!$V$5:$V$206,"<>REJEITADO") -> 1 | F31: =COUNTIFS('MAPA COMPARATIVO'!$F$5:$F$206,$A31,'MAPA COMPARATIVO'!$G$5:$G$206,"BAIXA",'MAPA COMPARATIVO'!$V$5:$V$206,"<>REJEITADO") -> 0 | G31: =SUM(C31:F31) -> 1 | H31: =SUMIFS('MAPA COMPARATIVO'!$O$5:$O$206,'MAPA COMPARATIVO'!$F$5:$F$206,$A31,'MAPA COMPARATIVO'!$V$5:$V$206,"<>REJEITADO") -> -457.84 | I31: =SUMIFS('MAPA COMPARATIVO'!$P$5:$P$206,'MAPA COMPARATIVO'!$F$5:$F$206,$A31,'MAPA COMPARATIVO'!$V$5:$V$206,"<>REJEITADO") -> -4821.36
A32: VERIFICAR | C32: =COUNTIFS('MAPA COMPARATIVO'!$F$5:$F$206,$A32,'MAPA COMPARATIVO'!$G$5:$G$206,"CRÍTICA",'MAPA COMPARATIVO'!$V$5:$V$206,"<>REJEITADO") -> 0 | D32: =COUNTIFS('MAPA COMPARATIVO'!$F$5:$F$206,$A32,'MAPA COMPARATIVO'!$G$5:$G$206,"ALTA",'MAPA COMPARATIVO'!$V$5:$V$206,"<>REJEITADO") -> 1 | E32: =COUNTIFS('MAPA COMPARATIVO'!$F$5:$F$206,$A32,'MAPA COMPARATIVO'!$G$5:$G$206,"MÉDIA",'MAPA COMPARATIVO'!$V$5:$V$206,"<>REJEITADO") -> 14 | F32: =COUNTIFS('MAPA COMPARATIVO'!$F$5:$F$206,$A32,'MAPA COMPARATIVO'!$G$5:$G$206,"BAIXA",'MAPA COMPARATIVO'!$V$5:$V$206,"<>REJEITADO") -> 17 | G32: =SUM(C32:F32) -> 32 | H32: =SUMIFS('MAPA COMPARATIVO'!$O$5:$O$206,'MAPA COMPARATIVO'!$F$5:$F$206,$A32,'MAPA COMPARATIVO'!$V$5:$V$206,"<>REJEITADO") -> 0 | I32: =SUMIFS('MAPA COMPARATIVO'!$P$5:$P$206,'MAPA COMPARATIVO'!$F$5:$F$206,$A32,'MAPA COMPARATIVO'!$V$5:$V$206,"<>REJEITADO") -> -4003.05
A33: TOTAL | C33: =SUM(C22:C32) -> 1 | D33: =SUM(D22:D32) -> 34 | E33: =SUM(E22:E32) -> 82 | F33: =SUM(F22:F32) -> 85 | G33: =SUM(G22:G32) -> 202 | H33: =SUM(H22:H32) -> 115594.89 | I33: =SUM(I22:I32) -> 399725.14

Sheet LEGENDA
A1: LEGENDA E NOTAS
A3: Objetivo | B3: Comparar, artigo a artigo, O QUE ESTÁ NO MQT com O QUE DEVERIA ESTAR, classificando falhas, erros e outros problemas, com impacto estimado em €.
A4: Origem dos dados | B4: MQT_CUSTO-VENDA.XLS (folha única). Qtd/Un/PU/Total copiados do original (texto azul).
A5: Método | B5: 1) Leitura integral e verificação aritmética por script; 2) revisão + varrimento por 5 grupos de capítulos; 3) verificação adversarial independente de cada achado (coluna Verificação: MANTIDO / CORRIGIDO / REJEITADO).
A6: Tipos | B6: ERRO (cálculo, unidade, numeração, texto) · FALHA/OMISSÃO (trabalho em falta) · DUPLICAÇÃO (pago 2×) · PREÇO BAIXO/ALTO (vs mercado) · INCOERÊNCIA (mesmo trabalho com preços/quantidades diferentes) · DESCRIÇÃO (texto incompatível/omisso) · NORMA (norma/lei errada ou em falta) · INCOMPATIBILIDADE (técnica) · EXTRA/FORA DE ÂMBITO · VERIFICAR (precisa de desenhos).
A7: Gravidade | B7: CRÍTICA = invalida o MQT ou > ~10 k€ / risco legal · ALTA = erro relevante de custo/técnico · MÉDIA = corrigir antes da adjudicação · BAIXA = forma/texto.
A8: Impacto (€) | B8: Cenário A = a menor variação plausível de cada achado; cenário B = a maior (mesmo sinal). Ordem de grandeza, sem IVA, Portugal 2025-2026. Negativo = retirar ao custo (duplicações, sobrepreços); positivo = acrescentar (omissões, subavaliações). Não substitui consultas ao mercado.
A9: Cores | B9: Azul = dado copiado do MQT ou estimativa introduzida · Verde = ligação a outra folha · Preto = fórmula · Amarelo = preencher/alterar pelo revisor.
A10: O que editar | B10: MAPA COMPARATIVO: colunas 'Estado de resolução' (lista) e 'Observações do revisor'. CUSTO vs VENDA: célula C3 (K). Todos os totais, a matriz e o painel recalculam.
A11: Limitações | B11: Sem peças desenhadas, caderno de encargos nem memória descritiva: medições não confirmadas contra o projeto; achados 'VERIFICAR' dependem dessa conferência.
A12: Fontes de referência | B12: LNEC – Número mínimo de ensaios em ancoragens (repositorio.lnec.pt); EN 1537 / EN ISO 22477-5; DL 266/2007 e Portaria 40/2014 (amianto); DL 163/2006 (acessibilidades); RT-SCIE; CCP arts. 50.º, 70.º–71.º e 378.º; Habitissimo (remoção de fibrocimento); Obramat (preço de material GL24h).
A14: Exemplo de preenchimento | B14: Estado de resolução = 'Corrigido no MQT'; Observações do revisor = 'Projetista confirmou duplicação; 2.2.2 eliminado na rev. B (15/10/2026)'.

Sheet MAPA COMPARATIVO
A1: MAPA COMPARATIVO DE FALHAS, ERROS E OUTROS – MQT CUSTO/VENDA
A2: Cada linha compara O QUE ESTÁ NO MQT com O QUE DEVERIA ESTAR. Valores em € sem IVA. Impacto: negativo reduz o custo, positivo aumenta. Colunas a amarelo = preencher pelo revisor.
A4: Nº | B4: Cap. | C4: Artigo | D4: Artigos relacionados | E4: Designação no MQT | F4: Tipo | G4: Gravidade | H4: Problema | I4: O QUE ESTÁ NO MQT | J4: Qtd MQT | K4: Un | L4: PU MQT (€) | M4: Total MQT (€) | N4: O QUE DEVERIA ESTAR (referência) | O4: Impacto A – mín (€) | P4: Impacto B – máx (€) | Q4: Impacto médio (€) | R4: Fundamentação | S4: Ação corretiva | T4: Responsável | U4: Origem | V4: Verificação | W4: Nota de verificação | X4: Estado de resolução | Y4: Observações do revisor
A5: 1 | B5: GERAL | C5: GERAL | D5: Colunas G/H (todos os artigos) | E5: Estrutura CUSTO/VENDA | F5: ERRO | G5: CRÍTICA | H5: VENDA = CUSTO: sem margem; venda 12,12 € abaixo do custo | I5: PU de venda igual ao PU de custo nos 833 artigos. Total custo 4.499.642,08 €; total venda 4.499.629,96 €; K implícito = 0,999997. | N5: Preço de venda = custo × K (estrutura + risco + lucro; tipicamente 1,15–1,25, definido pela empresa) ou composição de preço por artigo. | O5: 0 | P5: 0 | Q5: =AVERAGE(O5:P5) -> 0 | R5: Comparação direta das colunas E/G e F/H do ficheiro (script). Efeito de K calculado na folha CUSTO vs VENDA. | S5: Definir K por capítulo e recalcular a VENDA com fórmulas. | T5: Orçamentista | U5: EXISTENTE | V5: MANTIDO | W5: Verificado por script sobre o ficheiro original. | X5: Pendente
A6: 2 | B6: GERAL | C6: GERAL | D6: Todo o ficheiro | E6: Construção do ficheiro | F6: ERRO | G6: ALTA | H6: Ficheiro sem fórmulas: totais colados como valores | I6: 0 fórmulas em toda a folha; somas de capítulos e totais são números fixos. | N6: Totais = Qtd × PU e SUBTOTAL por capítulo, por fórmula. | O6: 0 | P6: 0 | Q6: =AVERAGE(O6:P6) -> 0 | R6: Conversão para .xlsx e contagem de fórmulas (openpyxl): 0. | S6: Refazer o MQT com fórmulas. | T6: Orçamentista | U6: EXISTENTE | V6: MANTIDO | W6: Verificado por script. | X6: Pendente
A7: 3 | B7: GERAL | C7: GERAL | D7: Fim do MQT | E7: Quadro-resumo | F7: FALHA/OMISSÃO | G7: ALTA | H7: Sem total geral, resumo por capítulos nem linha de IVA | I7: O MQT termina na nota 08; não há total geral nem indicação de IVA. | N7: Quadro-resumo por capítulo, total geral, 'IVA não incluído' e taxa aplicável. | O7: 0 | P7: 0 | Q7: =AVERAGE(O7:P7) -> 0 | R7: Leitura integral do ficheiro. | S7: Acrescentar quadro-resumo. | T7: Orçamentista | U7: EXISTENTE | V7: MANTIDO | W7: Verificado por leitura. | X7: Pendente
A8: 4 | B8: 2 | C8: 2.2.1 | D8: 2.2.2; 2.3.1; 2.3.3 | E8: MICROESTACAS | F8: VERIFICAR | G8: ALTA | H8: Microestacas 'para fundação' na contenção: possível duplicação com 2.3.1 | I8: 2.2.1 (subcapítulo 2.2 CONTENÇÃO PERIFÉRICA): 'Execução de microestaca para fundação, com um comprimento médio de 8,50 m...', 599,85 ml × 90,03 € = 54.005,32 €, seguida de 2.2.2 MACIÇO DE ENCABEÇAMENTO de estacas 63,00 m3. Em 2.3 OBRA DE BETÃO repete-se o mesmo par: 2.3.1 'microestaca para fundação' (L média 12,15 m; 525,22 + 555,11 = 1.080,33 ml) + 2.3.3 maciços 63,11 m3. | J8: 599.85 | K8: ml | L8: 90.03 | M8: 54005.32 | N8: Uma contenção tipo Berlim tem os seus próprios elementos verticais (perfis selados 2.2.3–2.2.5, 899,98 ml) e viga de coroamento (2.2.7). Microestacas 'para fundação' com maciços de encabeçamento são fundações (2.3). Cada microestaca deve aparecer uma só vez, com a função indicada. | O8: 0 | P8: -54005.32 | Q8: =AVERAGE(O8:P8) -> -27002.66 | R8: O par 'microestaca para fundação + maciço de encabeçamento' aparece duas vezes, com comprimentos médios diferentes (8,50 m e 12,15 m) e cerca de 71 un e 89 un, mas com volumes de maciços quase iguais (63,00 e 63,11 m3). Isto aponta para uma versão anterior das fundações que ficou no subcapítulo 2.2. Se for o caso, 2.2.1 está a mais (−54.005,32 €). Se forem microestacas reais de outro elemento, a descrição tem de dizer qual. | S8: Confirmar nas peças desenhadas a que elementos correspondem as cerca de 71 microestacas de 2.2.1 e depois eliminar o artigo ou corrigir a descrição e o subcapítulo. | T8: Projetista | U8: NOVO | V8: MANTIDO | W8: Confirmado no dump (linhas Excel 37, 39, 87–91, 95): 2.2.1 599,85 ml × 90,03 = 54.005,32 € (CUSTO), texto 'microestaca para fundação' L 8,50 m; 2.3.1 L 12,15 m com 525,22 + 555,11 = 1.080,33 ml; 599,85/8,5 = 70,6 un e 1.080,33/12,15 = 88,9 un. A palavra 'microestaca' só existe em 2.2.1 e 2.3.1 em todo o MQT. Os volumes de maciços quase iguais (63,00/63,11 m3) reforçam a hipótese de versão duplicada. O impacto vai de 0 a −54.005,32 €, porque o achado é de verificação. Mantido apesar de ser NOVO, porque a incoerência textual é objetiva. | X8: Pendente
A9: 5 | B9: 2 | C9: 2.2.1 | D9: 2.3.1.1 | E9: MICROESTACAS | F9: INCOERÊNCIA | G9: ALTA | H9: Microestaca 101,6×6,5 a 90,03 €/ml e a 134,17 €/ml (+49%) | I9: 2.2.1: 599,85 ml × 90,03 € = 54.005,32 € (N80 101,6×6,5 mm, Ø200, IRS, L média 8,50 m). 2.3.1.1 '101.6x6.5': 525,22 ml × 134,17 € = 70.469,71 € (mesma especificação, L média 12,15 m). | J9: 599.85 | K9: ml | L9: 90.03 | M9: 54005.32 | N9: Um só PU para a mesma microestaca: 90–105 €/ml (o PU de 2.2.1 já é um valor de mercado). | O9: -15320.67 | P9: -23183.21 | Q9: =AVERAGE(O9:P9) -> -19251.94 | R9: Diferença de 44,14 €/ml (+49,0%). Alinhando 2.3.1.1 a 90,03 €/ml: (90,03−134,17)×525,22 = −23.183,21 €. A 105 €/ml: −15.320,67 €. A falta de ensaios de carga está tratada em 2.3.1 (OMISSÃO). | S9: Uniformizar o PU das microestacas 101,6×6,5 (2.2.1 e 2.3.1.1). | T9: Orçamentista | U9: EXISTENTE | V9: MANTIDO | W9: Conferido: 2.2.1 599,85 × 90,03, total 54.005,32; 2.3.1.1 525,22 × 134,17, total 70.469,71. 134,17/90,03 = 1,490. Impactos recomputados (−23.183,21 € e −15.320,67 €). Não há dupla contagem com o achado de duplicação de 2.2.1, porque este ajusta o PU de 2.3.1.1 e não o de 2.2.1. | X9: Pendente
A10: 6 | B10: 2 | C10: 2.2.2 | D10: 2.3.3; 2.2.1 | E10: MACIÇOS DE FUNDAÇÃO | F10: DUPLICAÇÃO | G10: ALTA | H10: Maciços de encabeçamento repetidos em 2.2.2 e 2.3.3 (63,00/63,11 m3) | I10: 2.2.2: 63,00 m3 × 317,40 € = 19.996,33 € (C30/37, XC2, Cl0.40, S3, Dinf 2mm, Dsup 20mm, hidrófugo). 2.3.3: 63,11 m3 × 318,79 € = 20.119,03 €, com texto igual palavra a palavra exceto 'S4'. | J10: 63 | K10: m3 | L10: 317.4 | M10: 19996.33 | N10: Um único artigo de maciços de encabeçamento com a quantidade do projeto (cerca de 63 m3), a não ser que os desenhos mostrem dois conjuntos distintos de maciços. | O10: 0 | P10: -19996.33 | Q10: =AVERAGE(O10:P10) -> -9998.165 | R10: Os volumes diferem 0,17% e as descrições são iguais exceto na consistência (S3/S4). Como há dois conjuntos de microestacas (2.2.1 e 2.3.1), dois conjuntos de maciços podem justificar-se. A duplicação é provável mas não está provada. Se se confirmar, o artigo a eliminar vale 19.996,33 €. | S10: Confirmar nos desenhos de estabilidade. Se for duplicação, eliminar 2.2.2. Se não for, explicar na descrição a que microestacas se refere cada artigo. | T10: Projetista | U10: EXISTENTE | V10: MANTIDO | W10: Valores conferidos em rows.json: 2.2.2 q=63,00, PU 317,40, total CUSTO 19.996,33 (VENDA 19.996,20); 2.3.3 q=63,11, PU 318,79, total 20.119,03. Comparação dos textos: iguais exceto S3/S4. 0,11/63 = 0,17%. Impacto e gravidade coerentes. | X10: Pendente
A11: 7 | B11: 2 | C11: 2.2.5 | D11: 2.3.1.2 | E11: PERFIS SELADOS TUBULARES | F11: INCOERÊNCIA | G11: ALTA | H11: Microestaca 88,9×6,5 a 74,57 €/ml e a 126,31 €/ml (+69%) | I11: 2.2.5: 275,28 ml × 74,57 € = 20.528,28 € (tubo N80 88,9×6,5 mm, Ø200, IRS, L 9–10 m). 2.3.1.2 '88.9x6.5': 555,11 ml × 126,31 € = 70.116,04 € (mesma especificação, L média 12,15 m). | J11: 275.28 | K11: ml | L11: 74.57 | M11: 20528.28 | N11: Um só PU para a mesma microestaca 88,9×6,5 N80 IRS: 75–90 €/ml. Um comprimento maior não encarece o metro. | O11: -20156.04 | P11: -28721.39 | Q11: =AVERAGE(O11:P11) -> -24438.715 | R11: Diferença de 51,74 €/ml (+69,4%). Alinhando 2.3.1.2 a 74,57 €/ml: (74,57−126,31)×555,11 = −28.721,39 €. A 90 €/ml: (90−126,31)×555,11 = −20.156,04 €. | S11: Uniformizar o PU (2.2.5 e 2.3.1.2) ou justificar a diferença por escrito. | T11: Orçamentista | U11: EXISTENTE | V11: MANTIDO | W11: Conferido: 2.2.5 q=275,28, PU 74,57, total 20.528,28; 2.3.1.2 q=555,11, PU 126,31, total 70.116,04. 126,31/74,57 = 1,694 (+69,4%). Cálculos recomputados: −28.721,39 € e −20.156,04 €. Os textos têm a mesma especificação (N80, Ø200, leitada CEM I 42,5N a/c 0,4, IRS). As microestacas de fundação podem ter custos de acesso um pouco maiores, mas não justificam +69%. | X11: Pendente
A12: 8 | B12: 2 | C12: 2.2.12 | D12: 2.2.12.1; 2.2.12.2; 2.2.12.3 | E12: ANCORAGENS | F12: NORMA | G12: ALTA | H12: Só 2 ancoragens ensaiadas em 13; falta destensionamento | I12: 2.2.12.1: 5 UN × 1.533,59 € (400 kN, Llivre 5,50 + Lbolbo 9,00). 2.2.12.2: 4 UN × 1.586,48 € (400 kN, 5,00 + 10,00). 2.2.12.3: 4 UN × 1.374,95 € (200 kN, 6,00 + 7,00). Total 19.513,67 €, 13 ancoragens, todas a 105,77 €/ml. Texto: 'ancoragens provisórias, com / capacidade de carga,' (valor em branco) e 'ensaio de 2 ancoragens'. | N12: NP EN 1537, EN ISO 22477-5 e NP EN 1997-1 (8.8) exigem ensaio de receção em TODAS as 13 ancoragens, mais ensaios de investigação/aptidão. É preciso também destensionar e desativar as provisórias no fim, e ter autorização dos confinantes se os bolbos entrarem em terreno alheio. | O12: 3500 | P12: 7050 | Q12: =AVERAGE(O12:P12) -> 5275 | R12: 11 ensaios de receção adicionais × 150–250 € + 2–3 ensaios de aptidão × 600–1.000 € + destensionamento de 13 un × 50–100 € = 3.500–7.050 €. O PU por metro é igual (105,77 €/ml) para 200 kN e 400 kN, sinal de preço paramétrico. | S12: Exigir ensaio de receção em todas as ancoragens e ensaios de aptidão, acrescentar o destensionamento e completar a capacidade de carga em falta no texto. | T12: Projetista | U12: EXISTENTE | V12: MANTIDO | W12: Conferido: totais 7.667,97 + 6.345,91 + 5.499,79 = 19.513,67 €. PU/ml: 1.533,59/14,5 = 105,765; 1.586,48/15 = 105,765; 1.374,95/13 = 105,765, todos iguais. Texto 'com / capacidade de carga' (em branco) e 'ensaio de 2 ancoragens' confirmados. Impacto recomputado: 11×150 + 2×600 + 13×50 = 3.500; 11×250 + 3×1.000 + 13×100 = 7.050. | X12: Pendente
A13: 9 | B13: 2 | C13: 2.2.13 | D13: 2.2.12 | E13: SISTEMA DE MONITORIZAÇÃO | F13: PREÇO BAIXO | G13: ALTA | H13: Monitorização de contenção ancorada e vistorias por 3.500 € | I13: 1 UN × 3.500,00 € = 3.500,00 €. Inclui 'plano de instrumentação e monitorização', 'vistorias aos edifícios envolventes', 'fornecimento, aplicação e manutenção dos equipamentos' e 'leitura de medições durante o decurso da Empreitada'. | J13: 1 | K13: UN | L13: 3500 | M13: 3500 | N13: 10.000–20.000 € para uma contenção ancorada com 13 ancoragens: vistorias prévias com relatório, alvos topográficos e outros instrumentos previstos, leituras periódicas e relatórios durante a escavação. | O13: 6500 | P13: 16500 | Q13: =AVERAGE(O13:P13) -> 11500 | R13: (10.000−3.500) = 6.500 € e (20.000−3.500) = 16.500 €. Só as vistorias com relatório aos edifícios confinantes absorvem a maior parte dos 3.500 €. | S13: Rever o PU para 10–20 k€, de acordo com o plano de instrumentação do projeto. | T13: Orçamentista | U13: EXISTENTE | V13: MANTIDO | W13: Texto e valor (1 UN × 3.500) confirmados. As únicas ocorrências de 'monitoriza' no MQT são 2.2.13 e 7.5.2 (especialidade), e 'vistoria' só aparece em 2.2.13, por isso não há outro artigo que pague isto. A referência é plausível para a obra (13 ancoragens, cerca de 900 ml de perfis) e os cálculos estão corretos. | X13: Pendente
A14: 10 | B14: 2 | C14: 2.3.1 (OMISSÃO) | D14: 2.2.1; 2.2.5; 2.3.1; 2.2.12; 2.1.4 | E14: Ensaios de carga e controlo de qualidade | F14: FALHA/OMISSÃO | G14: ALTA | H14: Sem ensaios de carga de microestacas nem controlo de betão, aço ou aterros | I14: Nenhum artigo de ensaios de carga para 1.955,46 ml de microestacas (2.2.1: 599,85; 2.2.5: 275,28; 2.3.1: 1.080,33), nem de controlo de receção de cerca de 1.383 m3 de betão (2.2–2.3), do aço ou da compactação. Nos caps. 1–2 só 2.1.4 (Proctor) e 2.2.12 ('ensaio de 2 ancoragens') falam em ensaios. | N14: NP EN 14199 e NP EN 1997-1 (7.5): ensaios de carga estáticos de microestacas (pelo menos 2 un) e/ou ensaios de integridade. DL 90/2021 com NP EN 13670/NP EN 206: controlo de receção do betão (ensaios de identidade) e do aço. Ensaios de placa ou de densidade nos aterros. | O14: 8000 | P14: 18000 | Q14: =AVERAGE(O14:P14) -> 13000 | R14: 2 ensaios estáticos × 3.000–6.000 € = 6.000–12.000 €, mais 2.000–6.000 € de controlo de betão, aço e compactação = 8.000–18.000 €. | S14: Criar artigos de ensaios de carga de microestacas e de plano de controlo de qualidade (betão, aço, aterros). | T14: Projetista | U14: EXISTENTE | V14: MANTIDO | W14: Pesquisa de 'ensaio' em todas as 833 linhas: 2.1.4, 2.2.12 e depois apenas especialidades (4.5.7, 5.4.5, 6.3.4, 7.9.9, 7.12, 10.5.2, 11.15, 12.2), todas de redes, instalações ou condutas. Não há ensaios de estacas, betão ou aço. Somas conferidas: 599,85 + 275,28 + 525,22 + 555,11 = 1.955,46 ml; m3 de betão em 2.2–2.3 = 1.383,34. | X14: Pendente
A15: 11 | B15: 2 | C15: 2.3.1 | D15: 2.3.1 (OMISSÃO); 2.2.1; 2.2.5 | E15: MICROESTACAS | F15: FALHA/OMISSÃO | G15: ALTA | H15: Microestacas de fundação sem ensaios de carga | I15: 2.3.1.1: 525,22 ml × 134,17 € = 70.469,71 €. 2.3.1.2: 555,11 ml × 126,31 € = 70.116,04 €. O texto não inclui ensaios e nenhum outro artigo os prevê. | N15: Ensaios de carga estáticos (pelo menos 1–2 un) e/ou ensaios de integridade segundo a NP EN 14199 e a NP EN 1997-1 (7.5), de acordo com o caderno de encargos. | O15: 0 | P15: 0 | Q15: =AVERAGE(O15:P15) -> 0 | R15: Nos caps. 1–2 só 2.1.4 e 2.2.12 falam em ensaios. O impacto está quantificado em '2.3.1 (OMISSÃO)', para não contar duas vezes. | S15: Ver 2.3.1 (OMISSÃO). | T15: Projetista | U15: EXISTENTE | V15: MANTIDO | W15: Valores confirmados. A pesquisa de 'ensaio' no MQT inteiro não encontra ensaios de estacas. O impacto nulo evita a dupla contagem com '2.3.1 (OMISSÃO)'. | X15: Pendente
A16: 12 | B16: 2 | C16: 2.3.3 | D16: 2.2.2 | E16: MACIÇOS DE FUNDAÇÃO | F16: DUPLICAÇÃO | G16: ALTA | H16: Par de 2.2.2 (63,11 vs 63,00 m3), com S4 em vez de S3 | I16: 2.3.3: 63,11 m3 × 318,79 € = 20.119,03 € (C30/37, XC2, Cl0.40, S4). 2.2.2: 63,00 m3 × 317,40 € (S3), com texto igual. | J16: 63.11 | K16: m3 | L16: 318.79 | M16: 20119.03 | N16: Um só artigo. Se os dois forem reais, uniformizar a consistência (S3/S4) e o PU. | O16: 0 | P16: 0 | Q16: =AVERAGE(O16:P16) -> 0 | R16: É o mesmo par de 2.2.2. O impacto (até −19.996,33 €) está em 2.2.2, para não contar duas vezes. | S16: Ver 2.2.2. | T16: Projetista | U16: EXISTENTE | V16: MANTIDO | W16: Valores confirmados (linha Excel 95). O impacto nulo evita a dupla contagem com 2.2.2. | X16: Pendente
A17: 13 | B17: 2 | C17: 2.3.11 | D17: 2.3.9; 2.3.10; 2.3.12 | E17: VIGAS | F17: DESCRIÇÃO | G17: ALTA | H17: Vigas sem especificação do betão | I17: 101,63 m3 × 566,23 € = 57.546,06 €. Texto: '...compactação e cura de betão; transporte, montagem...', sem classe de resistência, exposição, cloretos, consistência nem Dsup. | J17: 101.63 | K17: m3 | L17: 566.23 | M17: 57546.06 | N17: Especificação completa segundo a NP EN 206, como nos artigos vizinhos (2.3.9/2.3.10: C30/37, XC1, Cl 0,40, S3, Dmáx 20 mm), de acordo com o projeto. | O17: 0 | P17: 0 | Q17: =AVERAGE(O17:P17) -> 0 | R17: Todos os outros artigos de betão do subcapítulo 2.3 têm especificação. Este é o único sem nenhuma. | S17: Completar a especificação do betão das vigas. | T17: Projetista | U17: EXISTENTE | V17: MANTIDO | W17: Linha Excel 112: texto sem classe de betão, confirmado. q=101,63, PU 566,23, total CUSTO 57.546,06. 2.3.9 e 2.3.10 com C30/37, XC1, Cl 0.40, S3, Dmáx 20 mm, confirmado. | X17: Pendente
A18: 14 | B18: 2 | C18: 2.5.1 | D18: 2.5.1.1 a 2.5.1.9 | E18: COBERTURA MADEIRA | F18: NORMA | G18: ALTA | H18: Classe de madeira ME-1 + GL24h contraditória, sem tratamento nem fogo; PU elevado | I18: 9 subartigos com 133,50 m3 de madeira, num total de 308.931,74 € (média de 2.314 €/m3; 2.304–2.361 €/m3 em todos exceto 2.5.1.8). Texto: 'COBERTURA EM MADEIRA em Pinho Silvestre da classe ME-1; GL24-h incluindo ligação entre vigas, ripas e barrotes'. Não indica classe de uso, tratamento preservador nem resistência ao fogo. | N18: Uma só especificação: madeira lamelada colada GL24h (EN 14080) ou madeira maciça C24/C27 (EN 338). A ME-1 é uma classe visual de madeira serrada de resinosas (UNE 56544). Falta a classe de uso (EN 335) com o respetivo tratamento e a resistência ao fogo (EN 1995-1-2). Referência de GL24h montado, com ligações e ripado incluídos: cerca de 1.760–2.200 €/m3. | O18: 0 | P18: -73963.92 | Q18: =AVERAGE(O18:P18) -> -36981.96 | R18: Madeira maciça classificada visualmente (ME-1) e lamelado colado (GL24h) são produtos diferentes. No retalho espanhol (Obramat) o GL24h custa cerca de 610–1.260 €/m3 com IVA (cerca de 500–1.040 €/m3 sem IVA). Somando fabrico, ligações, tratamento, transporte, grua e montagem (cerca de 700–900 €/m3) e uns 10% de ripas e barrotes incluídos no PU, a referência fica em 1.760–2.200 €/m3: (2.200−2.314)×133,50 = −15.221,96 € e (1.760−2.314)×133,50 = −73.963,92 €. Como o PU também paga ripas e barrotes (volume não medido) e falta prever tratamento e proteção ao fogo, que acrescentam custo, o PU atual pode estar correto. Por isso o cenário mínimo é 0. | S18: Corrigir a especificação (GL24h, EN 14080), acrescentar a classe de uso, o tratamento e a resistência ao fogo, e validar o PU com 2–3 propostas de fabricantes de lamelado. | T18: Projetista | U18: EXISTENTE | V18: CORRIGIDO | W18: Volume recalculado secção × comprimento: 133,504 m3. Soma 308.931,74 € e média 2.314,02 €/m3 confirmadas. €/m3 por linha: 2.304–2.361, e 1.743 em 2.5.1.8. Texto ME-1 + GL24-h confirmado. O problema normativo é real. A redução de preço não é demonstrável, porque o PU inclui ripas, barrotes e ligações não medidos em m3 e o tratamento e a proteção ao fogo em falta aumentariam o custo. impacto_min corrigido de −15.221,96 para 0; o máximo (−73.963,92 €) foi mantido. | X18: Pendente
A19: 15 | B19: 3 | C19: 3.1.1 | D19: 3.1.3; 3.1.4; 3.1.5; 3.1.7; 1.6 | E19: DEMOLIÇÃO DE PAVILHÃO EXISTENTE | F19: FALHA/OMISSÃO | G19: ALTA | H19: Demolição sem fundações, laje térrea nem transporte/destino final dos RCD | I19: 3.1.1 | m3 | Qtd 9 000 | PU 4,55 € | Total 40 950,00 €. Texto: «Demolição completa, elemento a elemento ... de edifício de cerca de 1200 m² ... e carga mecânica para camião ou contentor». Não refere fundações, laje térrea, transporte nem destino final. | J19: 9000 | K19: m3 | L19: 4.55 | M19: 40950 | N19: Demolição completa, incluindo fundações e pavimento térreo, e transporte e deposição dos RCD em operador licenciado com e-GAR (DL 102-D/2020). É a formulação dos art. 3.1.3, 3.1.4, 3.1.5 e 3.1.7 («transporte e descarga em vazadouro conforme o especificado no PGR»). O PU de 40 950 € / 1 200 m² ≈ 34 €/m² só é plausível para a demolição propriamente dita. | O19: 0 | P19: 30000 | Q19: =AVERAGE(O19:P19) -> 15000 | R19: Os restantes artigos de demolição do capítulo incluem expressamente transporte e vazadouro, mas o 3.1.1 termina na carga. RCD estimados: 1 200 m² × 1,0–1,5 t/m² = 1 200–1 800 t. A 8–15 €/t de transporte e deposição dá ≈10–27 k€. Fundações e laje térrea: ≈260 m³ × 25–40 €/m³ ≈ 6,5–10 k€. Mínimo de 0 € se o art. 1.6 (PGR, 25 000 €) cobrir o transporte e a deposição e se 'demolição completa' abranger as fundações. | S19: Completar a descrição do 3.1.1 com a demolição de fundações e laje térrea e com o transporte e deposição em operador licenciado, ou criar subartigos próprios, e clarificar a fronteira com o art. 1.6. | T19: Projetista | U19: EXISTENTE | V19: MANTIDO | W19: Confirmado em rows.json: m3, 9 000 × 4,55 = 40 950,00 €. O texto termina em «carga mecânica para camião ou contentor», enquanto 3.1.3, 3.1.4, 3.1.5 e 3.1.7 dizem «transporte e descarga em vazadouro» e o 3.1.7 refere fundações. O art. 1.6 é genérico («Implementação do PGR ... todos os trabalhos necessários»), pelo que o mínimo de 0 € está corretamente previsto. A ordem de grandeza do máximo é razoável. | X19: Pendente
A20: 16 | B20: 3 | C20: 3.1.2 | D20: 1.6; 3.1.1 | E20: DEMOLIÇÃO DE COBERTURA COM AMIANTO EM PAV. EXISTENTE | F20: FALHA/OMISSÃO | G20: ALTA | H20: Amianto sem transporte nem deposição licenciada | I20: 3.1.2 | m2 | Qtd 1 000 | PU 14,00 € | Total 14 000,00 €. Texto: «... por empresa qualificada ... superfície média a desmontar de cerca de 1000 m² ... e carga mecânica sobre camião. O preço inclui ... as medições da concentração de amianto (ambientais e pessoais)». | J20: 1000 | K20: m2 | L20: 14 | M20: 14000 | N20: Preço global de 20–30 €/m² (remoção, encapsulamento e embalagem, transporte com e-GAR e deposição em aterro licenciado para RCD com amianto), conforme a Portaria 40/2014 e a Portaria 145/2017 (e-GAR). Plano de trabalhos comunicado à ACT nos termos do DL 266/2007 (obrigação legal do executante). Área a confirmar com levantamento prévio de MCA, num edifício de ≈1 200 m². | O20: 0 | P20: 22000 | Q20: =AVERAGE(O20:P20) -> 11000 | R20: A descrição termina na carga sobre camião, sem transporte nem deposição. O PU de 14 €/m² é plausível só para a remoção (referência indicativa de ≈10 €/m² sem transporte e ≈20 €/m² com transporte a destino certificado). Diferença de preço: (20−14)×1 000 = 6 000 € a (30−14)×1 000 = 16 000 €. A eventual diferença de área (até +200 m² × 30 €) acrescenta até 6 000 €. Mínimo de 0 € se o art. 1.6 (PGR, 25 000 €) cobrir o transporte e a deposição, critério igual ao do achado 3.1.1. | S20: Reformular o 3.1.2 para incluir o embalamento, o transporte com e-GAR e a deposição em destino licenciado (ou remeter expressamente para o 1.6). Confirmar a área com levantamento de MCA e rever o PU para 20–30 €/m², se o transporte e a deposição ficarem neste artigo. | T20: Projetista | U20: EXISTENTE | V20: CORRIGIDO | W20: Números confirmados (1 000 × 14,00 = 14 000,00 €). Problema real (o texto acaba na carga), mas: (i) o mínimo passa a 0 €, porque o art. 1.6 (PGR) pode cobrir o transporte e a deposição, como se admitiu no 3.1.1; (ii) o plano de trabalhos ACT é obrigação legal do executante e não constitui omissão de custo, pelo que sai do título; (iii) a gravidade passa de CRÍTICA para ALTA, porque o artigo já prevê empresa qualificada e medições de amianto e a exposição é de 6–22 k€. A referência Habitissimo não é verificável nos dados e fica apenas como indicativa. | X20: Pendente
A21: 17 | B21: 3 | C21: 3.1.4 | D21: 3.1.4.1; 3.1.4.2; 3.1.4.3 | E21: DEMOLIÇÃO DE MUROS E MURETES | F21: PREÇO BAIXO | G21: ALTA | H21: 6,5 €/m3 para demolição manual de muros com vazadouro | I21: 3.1.4.1 | m3 | 74 | 6,50 € | 481,00 €; 3.1.4.2 | m3 | 10 | 6,50 € | 65,00 €; 3.1.4.3 | m3 | 40 | 6,50 € | 260,00 €. Total de 124 m³ = 806,00 €. Texto: «com meios manuais, e carga manual ... transporte e descarga em vazadouro». | N21: 45–80 €/m³ para demolição de alvenaria, betão armado ou granito com meios manuais ou martelo, com carga, transporte e vazadouro (mercado PT 2025-2026). | O21: 4774 | P21: 9114 | Q21: =AVERAGE(O21:P21) -> 6944 | R21: (45−6,5)×124 = 4 774 €; (80−6,5)×124 = 9 114 €. O PU de 6,5 €/m³ fica abaixo do da simples escavação com transporte do próprio MQT (art. 2.1.1 + 2.1.5 = 11 €/m³) e não cobre a demolição de betão armado e granito com meios manuais. | S21: Rever o PU dos três subartigos para 45–80 €/m³, diferenciando o betão armado e granito da alvenaria de bloco. | T21: Orçamentista | U21: EXISTENTE | V21: MANTIDO | W21: Quantidades 74/10/40 m³ a 6,50 € e totais 481/65/260 € confirmados (soma de 806 €). 2.1.1 e 2.1.5 estão ambos a 5,50 €/m³. Cálculo de impacto correto. Intervalo de referência plausível para demolição manual de muros com vazadouro. | X21: Pendente
A22: 18 | B22: 3 | C22: 3.3 (OMISSÃO) | D22: 3.13.6; 11.11 | E22: Linha de vida / sistema anti-queda na cobertura (omisso) | F22: FALHA/OMISSÃO | G22: ALTA | H22: Cobertura com acesso de manutenção sem linha de vida | I22: Nenhum artigo de linha de vida ou ancoragem (pesquisa sem resultados). Há ≈1 851 m² de cobertura em painel sandwich (3.3.1 e 3.3.2), 8 exutores em cobertura (11.11) e 3 escadas de acesso «de modo a aceder e manter todas as coberturas» (3.13.6). | N22: Sistema anti-queda permanente EN 795 (tipo C, cabo, e tipo A, pontos), certificado, para manutenção de coberturas leves não transitáveis, previsto na compilação técnica (DL 273/2003). | O22: 8000 | P22: 18000 | Q22: =AVERAGE(O22:P22) -> 13000 | R22: ≈140–200 ml de linha × 60–90 €/ml, mais pontos de ancoragem e certificação, dá ≈8–18 k€. O MQT prevê o acesso (3.13.6) e equipamentos a manter (exutores), mas não a proteção. | S22: Acrescentar um artigo de linha de vida com o traçado e a certificação. | T22: Projetista | U22: EXISTENTE | V22: MANTIDO | W22: Pesquisa sem resultados para 'linha de vida' e 'anti-queda'. 'ancoragem' só aparece no 2.2.12 (contenção) e no 13.6.4 (manta). 1 230 + 454 + 128 + 39 = 1 851 m². Confirmado o texto do 3.13.6 (3 UN, «aceder e manter todas as coberturas»). | X22: Pendente
A23: 19 | B23: 3 | C23: 3.9.2.3 | D23: 3.9.2.3.1; 3.9.2.3.2; 3.11.2.2 a 3.11.2.15 | E23: SOLEIRAS EXT. (betão polimérico tipo Tubani) | F23: DUPLICAÇÃO | G23: ALTA | H23: Soleiras exteriores pagas em 3.9.2.3 e nos artigos dos vãos | I23: 3.9.2.3.1 400 mm | ml | 112 | 85,00 € | 9 520,00 €; 3.9.2.3.2 200 mm | ml | 6 | 70,00 € | 420,00 €. Total 118 ml = 9 940 €. Os art. 3.11.2.2, 3.11.2.3, 3.11.2.4, 3.11.2.5, 3.11.2.6 a 3.11.2.13 e 3.11.2.15 dizem todos «Inclui soleira pré-fabricada de betão tipo TUBANI». O texto do 3.9.2.3 diz ainda «a aplicar em vãos interiores». | N23: Soleira paga uma só vez: no artigo do vão ou no 3.9.2.3. | O23: -9940 | P23: -9940 | Q23: =AVERAGE(O23:P23) -> -9940 | R23: Soma das larguras dos vãos exteriores cuja descrição inclui soleira Tubani: VE1.01 4,63 + VE1.02 2,50 + VE2.04 2,90 + VE1.03 1,20 + VE1.04/1.09/1.10 3×1,50 + VE2.08 1,40 + VE1.06 3,00 + VE2.01 3×5,33 + VE2.02 7×5,33 + VE2.03 3×5,33 + VE2.05 5,43 + VE2.05.01 2,17 + VE2.06 3,30 + VE2.07 2×6,10 + VE2.14 2,64 + VE1.05 2,61 = 117,77 ml. Isto coincide com os 118 ml do 3.9.2.3, que mede as mesmas soleiras. | S23: Retirar a soleira dos artigos de caixilharia (e reduzir os PU) ou anular o 3.9.2.3. Corrigir 'vãos interiores' para 'exteriores'. | T23: Projetista | U23: NOVO | V23: MANTIDO | W23: Soma recalculada: 117,77 ml, contra 112 + 6 = 118 ml. Os textos com «soleira pré-fabricada de betão tipo TUBANI» foram confirmados em todos os artigos listados (e também no 3.11.2.14, de vãos circulares, bem excluído da soma). O 3.9.2.3 diz «vãos interiores» apesar do título EXT. Valores de 9 520 € + 420 € = 9 940 € confirmados. Prova forte. | X23: Pendente
A24: 20 | B24: 3 | C24: 3.11.2.13.2 | D24: 3.11.2.13; 3.11.2.13.1; 3.11.2.24; 3.11.2.25 | E24: VE.2.14.1 com diâmetro 45cm | F24: ERRO | G24: ALTA | H24: Vão Ø45 cm a 5 174,40 €/un, já incluído no artigo-mãe | I24: 3.11.2.13.2 | UN | 2 | 5 174,40 € | 10 348,80 €. O artigo-mãe 3.11.2.13 (porta metálica TRIA TSN2 de 2 folhas) diz «Incluí 2 vãos de ventilação fixos tipo Navarra série 12000». A porta VE.2.14 (2,64x2,40) custa 4 840,00 €. | J24: 2 | K24: UN | L24: 5174.4 | M24: 10348.8 | N24: Um vão de ventilação circular custa 119,58 € (3.11.2.25, Ø300) a 438,64 € (3.11.2.24). Se VE.2.14.1 forem os 2 vãos de ventilação, já estão incluídos no artigo-mãe. | O24: 0 | P24: -10348.8 | Q24: =AVERAGE(O24:P24) -> -5174.4 | R24: Com descrição de vão Ø45 cm, o PU é 12 a 43 vezes o de vãos circulares semelhantes do MQT e superior ao da própria porta. Se for duplicação dos vãos incluídos no artigo-mãe: −10 348,80 €. Se o texto estiver errado e for outra porta: 0 €. | S24: Confirmar no mapa de vãos o que é VE.2.14.1. Corrigir a descrição ou o PU, ou eliminar o subartigo. | T24: Projetista | U24: EXISTENTE | V24: MANTIDO | W24: Confirmado em rows.json: 2 × 5 174,40 = 10 348,80 €. O artigo-mãe inclui textualmente «2 vãos de ventilação fixos tipo Navarra série 12000 com lâminas de ventilação». Rácios: 5 174,40/438,64 = 11,8× e /119,58 = 43,3× (≈12–43×). O achado é sólido. | X24: Pendente
A25: 21 | B25: 3 | C25: 3.11.2.26 | D25: 3.11.2.26.1; 3.11.2.26.2; 3.11.2.26 (OMISSÃO) | E25: SOLEIRAS EM CHAPA QUINADA (VE.C.01 / VE.1.11) | F25: FALHA/OMISSÃO | G25: ALTA | H25: Soleiras para 16 vãos sem artigo de caixilharia | I25: 3.11.2.26.1 VE.C.01 | UN | 8 | 51,60 € | 412,80 €; 3.11.2.26.2 VE.1.11 | UN | 8 | 51,60 € | 412,80 €. VE.C.01 e VE.1.11 não aparecem em nenhum outro artigo do MQT. | N25: Cada vão com soleira deve ter o artigo da caixilharia (dimensões, sistema e vidro), como os restantes VE. | O25: 0 | P25: 0 | Q25: =AVERAGE(O25:P25) -> 0 | R25: A pesquisa no MQT só encontra estas linhas para VE.C.01 e VE.1.11. O impacto está quantificado no achado 3.11.2.26 (OMISSÃO), para não contar duas vezes. | S25: Confirmar no mapa de vãos e acrescentar os artigos de caixilharia. | T25: Projetista | U25: EXISTENTE | V25: MANTIDO | W25: Pesquisa em rows.json: 'C.01' só aparece no 3.11.2.26.1. '1.11' só aparece no 3.11.2.26.2, na nota 05 (VI 1.11, que é outro vão) e no 3.15.4.3 (compartimento A.1.11). Os VE.1.11 não constam da lista de inexistentes da nota 05. Valores confirmados. | X25: Pendente
A26: 22 | B26: 3 | C26: 3.11.2.26 (OMISSÃO) | D26: 3.11.2.26.1; 3.11.2.26.2 | E26: Caixilharia dos vãos VE.C.01 e VE.1.11 (omissa) | F26: FALHA/OMISSÃO | G26: ALTA | H26: 16 vãos com soleira e sem caixilharia orçada | I26: VE.C.01 (8 UN) e VE.1.11 (8 UN) só existem nas soleiras 3.11.2.26, a 51,60 €. | N26: Artigos de caixilharia para os 16 vãos, a ≈0–1 500 €/vão consoante a dimensão (o VE.C.02 semelhante custa 471,36 €; vãos de ventilação 119–439 €). | O26: 0 | P26: 24000 | Q26: =AVERAGE(O26:P26) -> 12000 | R26: 16 × até 1 500 € = 24 000 €. Mínimo de 0 € se os vãos não levarem caixilho (por exemplo, aberturas livres). | S26: Confirmar no mapa de vãos e orçar. | T26: Projetista | U26: EXISTENTE | V26: MANTIDO | W26: Pesquisa confirma que não há outras ocorrências. Referências internas corretas (VE.C.02 a 471,36 €; 3.11.2.25 a 119,58 €; 3.11.2.24 a 438,64 €). O intervalo 0–24 000 € é coerente. | X26: Pendente
A27: 23 | B27: 3 | C27: 3.15.9 (OMISSÃO) | D27: 3.9.2.8; 3.15.9.1 | E27: Marcações do campo exterior PAV E 02 (omisso) | F27: FALHA/OMISSÃO | G27: ALTA | H27: Campo exterior sem linhas de jogo | I27: O 3.15.9 só tem marcações interiores: 3.15.9.1 (1 100 m²) e 3.15.9.2 (380 m²) a 2,50 €/m². O 3.9.2.8 (2 538 m²) não inclui linhas. | N27: Marcações multidesportivas em tinta compatível com o Sikafloor Colorsport. Pelo próprio PU do MQT (2,50 €/m²): 2 538 × 2,50 = 6 345 €. | O27: 1500 | P27: 6345 | Q27: =AVERAGE(O27:P27) -> 3922.5 | R27: ≈600–1 000 ml de linhas a 1,5–3 €/ml dá ≈1 500–3 000 €. Aplicando o critério do MQT por m², o máximo é 6 345 €. | S27: Acrescentar o subartigo 3.15.9.3 (campo exterior). | T27: Projetista | U27: EXISTENTE | V27: MANTIDO | W27: Confirmado que o 3.15.9 só tem os subartigos .1 e .2 (setores interiores) e que 'marcaç' não aparece noutro artigo. 2 538 × 2,50 = 6 345 € correto. | X27: Pendente
A28: 24 | B28: 3 | C28: 3.17 (OMISSÃO) | D28: 3.9.1.1; 3.9.2.8; 3.17.2 | E28: Equipamento desportivo (omisso) | F28: FALHA/OMISSÃO | G28: ALTA | H28: Sem balizas, tabelas, postes nem equipamento de ginásio | I28: Nenhum artigo do MQT inclui balizas, tabelas de basquetebol, postes ou redes de voleibol e badminton, ou equipamento de ginástica (pesquisa sem resultados). Só há redes de proteção (3.17.2), cortinas (3.17.7) e bancadas. | N28: Equipamento conforme o DL 100/2003 (balizas e equipamentos de basquetebol), a NP EN 749, a EN 1270, a EN 1271 e a EN 913, para o polidesportivo (1 100 m²), o ginásio (396 m²), a sala de ginástica e o campo exterior (2 538 m²). | O28: 35000 | P28: 70000 | Q28: =AVERAGE(O28:P28) -> 52500 | R28: Balizas: 4–6 × 1,5–3 k€. Tabelas principais e laterais: 15–35 k€. Voleibol e badminton: 2–4 k€. Ginásio: 10–20 k€. Total ≈35–70 k€. Impacto 0 € se o Dono de Obra fornecer o equipamento fora da empreitada. | S28: Decidir se o equipamento entra na empreitada e, nesse caso, criar os artigos com referências normativas. | T28: Dono de Obra | U28: EXISTENTE | V28: MANTIDO | W28: Pesquisa em todo o rows.json sem resultados para baliza, tabela, basquet, voleibol, badminton e espaldar. 'poste' só aparece em contextos não desportivos. O intervalo é plausível. A eventual exclusão pelo Dono de Obra está referida (responsável Dono de Obra). | X28: Pendente
A29: 25 | B29: 5 | C29: 5.3.7 | D29: 3.16.1.18; 6.2.16 | E29: CANAL COM GRELHA CHUVEIROS | F29: DUPLICAÇÃO | G29: ALTA | H29: Drenagem linear dos balneários paga em 5.3.7 e 3.16.1.18 | I29: 5.3.7: 25,60 m × 220,00 € = 5.632,00 €, 'caleiras de pavimento em ferro fundido ... aplicar nas cozinhas, e instalações sanitárias'. 3.16.1.18 'DRENAGEM LINEAR EM BALNEÁRIOS ... tipo ACO 64 em Aço Inox': 28,00 ml × 269,61 € = 7.549,08 €. | J29: 25.6 | K29: m | L29: 220 | M29: 5632 | N29: Uma só medição da drenagem linear dos balneários (3.16.1.18, inox, conforme arquitetura). O programa não tem cozinhas: a pesquisa de 'cozinha' no MQT só encontra 5.3.7. | O29: 0 | P29: 0 | Q29: =AVERAGE(O29:P29) -> 0 | R29: Mesma função (caleira de duche nos balneários) com comprimentos semelhantes (25,6 m vs 28 m) e materiais incompatíveis entre si (ferro fundido vs inox). Retirando o artigo duplicado, poupam-se 5.632 €. | S29: Eliminar 5.3.7, ou reduzi-lo à ligação à rede, e corrigir a referência a cozinhas. | T29: Projetista | U29: EXISTENTE | V29: MANTIDO | W29: Confirmei 25,6 × 220 = 5.632 € e 28 × 269,61 = 7.549,08 €, bem como os dois textos. 'cozinha' só aparece em 5.3.7. O 6.2.16 (ACO inox, 87,4 m) é drenagem pluvial exterior, não balneários, e não entra na duplicação. A duplicação entre especialidades é consistente. [Consolidação: impacto contabilizado em 3.16.1.18 para não contar duas vezes.] | X29: Pendente
A30: 26 | B30: 6 | C30: 6.1.1 | D30: 6.1.3; 2.1.2; 2.1.5 | E30: ESCAVAÇÃO | F30: PREÇO BAIXO | G30: ALTA | H30: Vala com entivação por estacas-prancha/painéis a 5,50 €/m3 | I30: 6.1.1: 708,21 m3 × 5,50 €/m3 = 3.895,16 €. Texto: 'entivações e escoramento das valas com estacas prancha ou painéis metálicos ... montagem e desmontagem'. | J30: 708.21 | K30: m3 | L30: 5.5 | M30: 3895.16 | N30: 12–18 €/m3; com painéis de entivação pode passar dos 20 €/m3. Só a escavação e o transporte custam 16,50 €/m3 no próprio MQT (2.1.2 + 2.1.5). | O30: 4603.37 | P30: 8852.63 | Q30: =AVERAGE(O30:P30) -> 6728 | R30: (12 − 5,50) × 708,21 = 4.603,37 €; (18 − 5,50) × 708,21 = 8.852,63 €. Atenuante: a regularização 6.1.2 está a 46,66 €/m3 (170,53 m3 = 7.957,05 €), o que eleva o custo global da vala para cerca de 20,9 €/m3 escavado. Mesmo assim, fica abaixo de um orçamento de mercado completo (≈ 28 €/m3). | S30: Rever o PU (≥ 12–18 €/m3) ou medir a entivação à parte (m2). | T30: Orçamentista | U30: EXISTENTE | V30: MANTIDO | W30: Confirmei 708,21 × 5,50 = 3.895,16 € e o texto (estacas-prancha/painéis, montagem e desmontagem). As contas estão certas: 4.603,37 € e 8.852,63 €. Acrescentei à fundamentação a compensação parcial pelo PU elevado da areia (6.1.2). O achado mantém-se, porque o conjunto da vala continua abaixo do mercado. | X30: Pendente
A31: 27 | B31: 6 | C31: 6.2.8 | D31: 6.2.8.1; 6.2.8.2; 6.2.8.3; 2.6.5 | E31: GEODRENO | F31: PREÇO BAIXO | G31: ALTA | H31: Geodreno com brita, geotêxtil, vala e pavimentos a 3,56–10,60 €/m | I31: 6.2.8.1 DN100: 29,40 m × 3,56 €; 6.2.8.2 DN160: 420,00 m × 7,65 €; 6.2.8.3 DN200: 183,75 m × 10,60 €. Total 633,15 m / 5.265,41 €. Inclui 'brita 25/40 envolvida em geotêxtil ... levantamento e reposição de pavimentos, abertura e tapamento de vala'. | N31: 2.6.5 (dreno DN160 + brita 25/40 + geotêxtil em secção 0,40 × 0,40, sem vala nem pavimentos) = 20,32 €/ml. Mercado com vala: DN100 16–25, DN160 20–32, DN200 24–38 €/m. | O31: 8149 | P31: 15892 | Q31: =AVERAGE(O31:P31) -> 12020.5 | R31: Mínimo: (16 − 3,56) × 29,4 + (20,32 − 7,65) × 420 + (24 − 10,60) × 183,75 = 8.149 €. Máximo: (25 − 3,56) × 29,4 + (32 − 7,65) × 420 + (38 − 10,60) × 183,75 = 15.892 €. O PU do DN160 é 38% do dreno equivalente 2.6.5, que nem tem vala. | S31: Rever os PU (DN160 ≥ 20,32 €/m, em linha com 2.6.5). | T31: Orçamentista | U31: EXISTENTE | V31: MANTIDO | W31: Confirmei quantidades, PU e totais (104,66 + 3.213 + 1.947,75 = 5.265,41 €; 633,15 m). O 2.6.5 está a 20,32 €/ml, com a descrição citada. Recalculei: mínimo 8.149,39 € e máximo 15.892,09 €. 7,65 / 20,32 = 37,6%. | X31: Pendente
A32: 28 | B32: 6 | C32: 6.2.13 | D32: 6.2.13.1; 6.2.12.3; 6.2.5.7 | E32: CÂMARA DE VISITA NA LIGAÇÃO À TUBAGEM DE 500mm | F32: PREÇO BAIXO | G32: ALTA | H32: CV especial com caixa BA 1,5×1,5 e D400 a 545,62 € | I32: 6.2.13.1 'DN 1.25 e 1,50x1,50mm': 1 UN × 545,62 €. Inclui anéis DN1,25 até 3,00 m, caixa em BA 1,50 × 1,50 m com e = 0,20 m, tampa D400, escavação e envolvimento em C35/45 XA3. O título refere 'TUBAGEM DE 500mm', mas o maior DN no MQT é 400 (6.2.5.7). | N32: Tem de custar mais do que 6.2.12.3 (CV DN1,25 simples com h > 2,50 m = 644,83 €). Mercado: 2.500–5.000 €. Corrigir '1,50x1,50mm' para '1,50 × 1,50 m' e o DN da tubagem. | O32: 1954.38 | P32: 4454.38 | Q32: =AVERAGE(O32:P32) -> 3204.38 | R32: (2.500 − 545,62) = 1.954,38 €; (5.000 − 545,62) = 4.454,38 €. Incoerência interna: a câmara especial (545,62 €) sai mais barata do que a câmara simples DN1,25 (644,83 €). | S32: Rever o PU (decompor anéis, caixa BA, betão C35/45 e tampa D400) e corrigir o texto (DN500 inexistente, unidade 'mm'). | T32: Orçamentista | U32: EXISTENTE | V32: MANTIDO | W32: Confirmei o texto e o PU (1 × 545,62 €). As pesquisas de '500 mm' e 'DN 500' só encontram 6.2.13, e o maior coletor medido é o DN400 (6.2.5.7). As contas estão certas. | X32: Pendente
A33: 29 | B33: 6 | C33: 6.2.18 | D33: 6.2.18.1; 3.3.1; 3.3.2; 3.3.5; nota 02 | E33: CALEIRA – 200x100 mm | F33: DUPLICAÇÃO | G33: ALTA | H33: Caleiras de zinco já incluídas nos artigos de cobertura | I33: 6.2.18.1: 196,60 m × 40,00 € = 7.864,00 € ('caleiras ... em folha de zinco nº 12'). 3.3.1, 3.3.2 e 3.3.5 incluem 'caleira de drenagem de A.P.s ... tipo FTB'. A nota 02 diz: 'encontram-se incluídos ... rufos, ... caleiros ... Optou-se por não fazer a sua medição individualizada'. | N33: 0 € no cap. 6, porque as caleiras estão pagas nas coberturas (1.886 m2). Se o projeto exigir uma caleira de zinco diferente da do sistema FTB, tem de ser expressamente excluída de 3.3.x e da nota 02. | O33: -7864 | P33: -7864 | Q33: =AVERAGE(O33:P33) -> -7864 | R33: Os artigos de cobertura e a nota 02 incluem expressamente as caleiras, logo o 6.2.18 paga o mesmo trabalho pela segunda vez. | S33: Eliminar 6.2.18, ou excluir as caleiras de 3.3.x e da nota 02 e confirmar a compatibilidade do zinco com o sistema FTB. | T33: Projetista | U33: EXISTENTE | V33: MANTIDO | W33: Confirmei 196,6 × 40 = 7.864 €. Os textos de 3.3.1, 3.3.2 e 3.3.5 incluem 'caleira de drenagem de A.P.s ... tipo FTB', e a nota 02 (linha 256) inclui 'caleiros' em todos os artigos de cobertura. Áreas: 1.230 + 454 + 128 + 39 + 35 = 1.886 m2. As coberturas 3.3.3/3.3.4 são planas e também estão abrangidas pela nota 02. A duplicação está bem suportada. | X33: Pendente
A34: 30 | B34: 7 | C34: 7 | D34: 7.4.1–7.4.5; 7.5.1; 7.5.3; 7.7.3.1.1–7.7.3.1.8; 7.7.3.2.1/2/4; 7.9.1; 7.9.5; 7.9.7 | E34: INSTALAÇÕES ELÉTRICAS | F34: DESCRIÇÃO | G34: ALTA | H34: Equipamentos principais do Cap. 7 sem especificação técnica | I34: Designações sem características: 7.4.1 'Q.G.P.' 1 UN × 2.648,86 €; 7.4.2 'Q.P.C.I.G.' 9.541,74 €; 7.5.1 'Inversor Solar' 3 UN × 1.699,55 €; 7.5.3 'Paineis Solares' 192 UN × 132,84 € = 25.505,28 €; 7.7.3.1.1–8 '.Tipo L1'…'.Tipo P3' = 62.857,82 €; 7.7.3.2.x '. Tipo S1/S2/S3' = 7.393,08 €; 7.9.1 'Consola', 7.9.5 'Switch dedicado', 7.9.7 'Servidor'. Soma = 124.345,57 € (46,7 % do Cap. 7 = 265.980,37 €) | M34: 265980.37 | N34: Cada artigo deve definir as características mínimas ou remeter expressamente para a ficha do C.E./peças desenhadas: QGP (In do corte geral, Icc, forma, IP/IK), inversor (kW AC), painel (Wp, tecnologia, garantia), luminária (lm, W, IP/IK, UGR, Ra). Ver Portaria 701-H/2008 (conteúdo das medições e do mapa de quantidades do projeto de execução) | O34: 0 | P34: 0 | Q34: =AVERAGE(O34:P34) -> 0 | R34: Soma calculada no rows.json: 18.364,21 (7.4) + 5.098,65 + 25.505,28 + 62.857,82 + 7.393,08 + 1.670,80 + 773,69 + 2.682,04 = 124.345,57 €. Ao contrário destes, os artigos do Cap. 10 (ex.: 10.1.1) remetem para 'peças escritas e desenhadas'. Sem esta definição não é possível validar preços nem exigir conformidade, e abre-se a porta a substituições por equipamento inferior. | S34: Pedir ao projetista as fichas técnicas e completar as descrições no MQT (ou incluir remissão explícita para o C.E.). Usá-las como base nas consultas a subempreiteiros. | T34: Projetista | U34: EXISTENTE | V34: MANTIDO | W34: Conferidos todos os PU/totais no rows.json: soma dos 8 L/P = 62.857,82 €; S1+S2+S3 = 1.734,48+3.814,00+1.844,60 = 7.393,08 €; soma global 124.345,57 € = 46,75 % de 265.980,37 €. As designações são de facto só códigos ('.Tipo L1', 'Q.G.P.'), sem remissão para o C.E. (ao contrário de 10.1.1/10.1.2/10.3.1 e 11.14.1). | X34: Pendente
A35: 31 | B35: 7 | C35: 7 (OMISSÃO) | D35: 7.3; 7.4.1; 7.5 | E35: SPDA – proteção contra descargas atmosféricas | F35: FALHA/OMISSÃO | G35: ALTA | H35: Sem SPDA nem descarregadores de sobretensões | I35: Nenhum artigo de captores, descidas, ligadores de medição ou elétrodos de SPDA, nem de descarregadores. 7.3 'Rede Terra' = 5.271,03 € | N35: Análise de risco segundo a NP EN 62305-2 e, se exigido, SPDA segundo a NP EN 62305-3 (cobertura de grande área com 192 módulos FV). SPD tipo 1/2 no QGP (RTIEBT secções 443/534) | O35: 1000 | P35: 20000 | Q35: =AVERAGE(O35:P35) -> 10500 | R35: Pesquisa em todo o MQT ('raio', 'descarreg', 'SPDA', 'sobretens', 'captor') sem resultados relevantes. O edifício é de grande dimensão, de uso escolar/desportivo e tem gerador FV na cobertura. Mínimo: só SPD tipo 1+2 no QGP e tipo 2 nos quadros parciais/FV (≈ 1.000 €) se a análise de risco dispensar SPDA externo; máximo com SPDA completo ≈ 20.000 €. | S35: Pedir a análise de risco e o projeto de SPDA e criar os artigos. | T35: Projetista | U35: EXISTENTE | V35: CORRIGIDO | W35: Pesquisa refeita em todo o rows.json: 'raio' só aparece em 13.1.1 (árvores); 'descarreg', 'spda', 'sobretens', 'captor' com 0 resultados. Omissão real. Corrigido o impacto_min de 8.000 € para 1.000 €: a NP EN 62305-2 pode dispensar SPDA externo, ficando só os SPD (que também podem estar dentro do PU dos quadros). | X35: Pendente
A36: 32 | B36: 7 | C36: 7.5.3 | D36: 7.5.4; 7.5.5; 7.4.5 | E36: Paineis Solares | F36: DESCRIÇÃO | G36: ALTA | H36: UPAC sem potência definida, proteções DC/AC nem registo | I36: 7.5.3 'Paineis Solares' 192 UN × 132,84 €; 7.5.4 'Estrutura de suporte dos painéis' 1 UN × 10.161,49 €; 7.5.5 'Instalação Elétrica, parametrização e configuração do sistema, testes e colocação em serviço.' 1 UN × 5.281,80 €. Não há artigo de caixas de proteção de strings, descarregadores DC/AC, registo nem certificado de exploração | J36: 192 | K36: UN | L36: 132.84 | M36: 25505.28 | N36: DL 15/2022: uma UPAC entre 30 kW e 1 MW exige registo prévio e certificado de exploração. Proteções DC (seccionamento/fusíveis por string) e SPD tipo 2 DC/AC segundo a RTIEBT secção 712 / IEC 60364-7-712. Verificação estrutural da cobertura para a sobrecarga dos painéis | O36: 0 | P36: 2500 | Q36: =AVERAGE(O36:P36) -> 1250 | R36: A potência e a tecnologia não estão definidas, pelo que o preço não pode ser validado. Muitos inversores string já integram seccionador e SPD DC; as proteções AC podem estar no Q.PV.AC (2.683,37 €) e a colocação em serviço em 7.5.5. Parte possivelmente em falta: caixas DC externas 3 × 300–500 € + SPD adicional 0–300 € + registo/inspeção da UPAC 300–600 € ≈ 0–2.500 € (0 se tudo estiver integrado/incluído). | S36: Completar a descrição (Wp, tecnologia, garantias) e criar artigos para as proteções DC/AC e para o registo/certificado da UPAC. Pedir a verificação estrutural da cobertura. | T36: Projetista | U36: EXISTENTE | V36: CORRIGIDO | W36: Valores conferidos (192 × 132,84 = 25.505,28; 10.161,49; 5.281,80; Q.PV.AC 2.683,37). Pesquisa por 'descarreg', 'sobretens', 'registo', 'certific' sem artigos elétricos. Regime DL 15/2022 (30 kW–1 MW: registo prévio + certificado de exploração) correto. Corrigida a fundamentação: a decomposição original somava até 3.000 € e não tinha em conta que os inversores string costumam integrar proteções DC; o máximo de 2.500 € fica agora coerente com a decomposição. | X36: Pendente
