Workbook

Sheet RESUMO
B1: 050.24 - LAR DE S. JORGE, GMR
D2: MEDIÇÃO R01 (DWFx 22128.ES.EXE.PD.R00) | H2: CONFORME MQT E CCS | P2: MQT − MEDIÇÃO
B3: ARTIGO | C3: DESCRITIVO | D3: BETÃO (m3 ou m2) | E3: AÇO s/ EMP. (kg) | F3: AÇO c/ EMP. (kg) | G3: COFRAGEM (m2) | H3: BETÃO (m3 ou m2) | I3: AÇO (kg) | J3: COFRAGEM (m2) | L3: AÇO s/emp. x N4 (kg) | P3: BETÃO (m3 ou m2) | Q3: AÇO (kg) | R3: COFRAGEM (m2) | T3: BETÃO MODELO BIM (m3) | U3: OBSERVAÇÕES
B4: 20.2.1.1.1 | C4: Sapatas Contínuas | N4: 1.1
B5: 20.2.1.1.1.1 | C5: (Zona E) | D5: =SUMIF(FUNDAÇÕES!$AO:$AO,"E",FUNDAÇÕES!$G:$G) -> 8.3755 | E5: =SUMIF(FUNDAÇÕES!$AO:$AO,"E",FUNDAÇÕES!$AP:$AP) -> 500.68992 | F5: =E5+SUMIF(FUNDAÇÕES!$AO:$AO,"E",FUNDAÇÕES!$AQ:$AQ) -> 500.68992 | G5: =SUMIF(FUNDAÇÕES!$AO:$AO,"E",FUNDAÇÕES!$I:$I) -> 18.55 | H5: 8.377 | I5: 783 | J5: 16.01 | L5: =E5*$N$4 -> 550.75891 | P5: =IF(ISNUMBER(H5),H5-D5,"") -> 0.0015 | Q5: =IF(ISNUMBER(I5),I5-F5,"") -> 282.31008 | R5: =IF(ISNUMBER(J5),J5-G5,"") -> -2.54 | T5: =SUMIF(FUNDAÇÕES!$AO:$AO,"E",FUNDAÇÕES!$AR:$AR) -> 8.3755 | U5: SMS1.1 a SMS1.4 (ES0401). Volume = modelo; armadura conforme det. 3-5.
B6: 20.2.1.1.2 | C6: Sapatas Isoladas
B7: 20.2.1.1.2.1 | C7: (Zona A) | D7: =SUMIF(FUNDAÇÕES!$AO:$AO,"A",FUNDAÇÕES!$G:$G) -> 10.694 | E7: =SUMIF(FUNDAÇÕES!$AO:$AO,"A",FUNDAÇÕES!$AP:$AP) -> 1525.218 | F7: =E7+SUMIF(FUNDAÇÕES!$AO:$AO,"A",FUNDAÇÕES!$AQ:$AQ) -> 1540.9236 | G7: =SUMIF(FUNDAÇÕES!$AO:$AO,"A",FUNDAÇÕES!$I:$I) -> 23.79 | H7: 10.694 | I7: 1294 | J7: 25.26 | L7: =E7*$N$4 -> 1677.7398 | P7: =IF(ISNUMBER(H7),H7-D7,"") -> 0 | Q7: =IF(ISNUMBER(I7),I7-F7,"") -> -246.9236 | R7: =IF(ISNUMBER(J7),J7-G7,"") -> 1.47 | T7: =SUMIF(FUNDAÇÕES!$AO:$AO,"A",FUNDAÇÕES!$AR:$AR) -> 10.499 | U7: S6-S11 (ES0101). S10 medida com H=0.60 do quadro (modelo tem 0.50). Inclui esperas dos pilares.
B8: 20.2.1.1.2.2 | C8: (Zona B) | D8: =SUMIF(FUNDAÇÕES!$AO:$AO,"B",FUNDAÇÕES!$G:$G) -> 7.105 | E8: =SUMIF(FUNDAÇÕES!$AO:$AO,"B",FUNDAÇÕES!$AP:$AP) -> 1114.26 | F8: =E8+SUMIF(FUNDAÇÕES!$AO:$AO,"B",FUNDAÇÕES!$AQ:$AQ) -> 1133.4408 | G8: =SUMIF(FUNDAÇÕES!$AO:$AO,"B",FUNDAÇÕES!$I:$I) -> 22.6 | H8: 7.105 | I8: 860 | J8: 16.79 | L8: =E8*$N$4 -> 1225.686 | P8: =IF(ISNUMBER(H8),H8-D8,"") -> 0 | Q8: =IF(ISNUMBER(I8),I8-F8,"") -> -273.4408 | R8: =IF(ISNUMBER(J8),J8-G8,"") -> -5.81 | T8: =SUMIF(FUNDAÇÕES!$AO:$AO,"B",FUNDAÇÕES!$AR:$AR) -> 7.105 | U8: S1 x5 e S5 x4 (ES0201). Inclui esperas.
B9: 20.2.1.1.2.3 | C9: (Zona C) | D9: =SUMIF(FUNDAÇÕES!$AO:$AO,"C",FUNDAÇÕES!$G:$G) -> 16.576 | E9: =SUMIF(FUNDAÇÕES!$AO:$AO,"C",FUNDAÇÕES!$AP:$AP) -> 1472.5824 | F9: =E9+SUMIF(FUNDAÇÕES!$AO:$AO,"C",FUNDAÇÕES!$AQ:$AQ) -> 1507.7472 | G9: =SUMIF(FUNDAÇÕES!$AO:$AO,"C",FUNDAÇÕES!$I:$I) -> 44.72 | H9: 16.576 | I9: 2006 | J9: 39.16 | L9: =E9*$N$4 -> 1619.8406 | P9: =IF(ISNUMBER(H9),H9-D9,"") -> 0 | Q9: =IF(ISNUMBER(I9),I9-F9,"") -> 498.2528 | R9: =IF(ISNUMBER(J9),J9-G9,"") -> -5.56 | T9: =SUMIF(FUNDAÇÕES!$AO:$AO,"C",FUNDAÇÕES!$AR:$AR) -> 16.576 | U9: S2 x4, S3 x9, S4 x2 (ES0301). Inclui esperas.
B10: 20.2.1.1.2.4 | C10: (Zona D) | D10: =SUMIF(FUNDAÇÕES!$AO:$AO,"D",FUNDAÇÕES!$G:$G) -> 0.605 | E10: =SUMIF(FUNDAÇÕES!$AO:$AO,"D",FUNDAÇÕES!$AP:$AP) -> 61.248 | F10: =E10+SUMIF(FUNDAÇÕES!$AO:$AO,"D",FUNDAÇÕES!$AQ:$AQ) -> 61.248 | G10: =SUMIF(FUNDAÇÕES!$AO:$AO,"D",FUNDAÇÕES!$I:$I) -> 2.2 | H10: 0.605 | I10: 73 | J10: 1.43 | L10: =E10*$N$4 -> 67.3728 | P10: =IF(ISNUMBER(H10),H10-D10,"") -> 0 | Q10: =IF(ISNUMBER(I10),I10-F10,"") -> 11.752 | R10: =IF(ISNUMBER(J10),J10-G10,"") -> -0.77 | T10: =SUMIF(FUNDAÇÕES!$AO:$AO,"D",FUNDAÇÕES!$AR:$AR) -> 0.605 | U10: SE1 (ES0401 rotula como Zona E).
B11: 20.2.1.1.2.5 | C11: (Zona F) | D11: =SUMIF(FUNDAÇÕES!$AO:$AO,"F",FUNDAÇÕES!$G:$G) -> 4.3155 | E11: =SUMIF(FUNDAÇÕES!$AO:$AO,"F",FUNDAÇÕES!$AP:$AP) -> 264.32208 | F11: =E11+SUMIF(FUNDAÇÕES!$AO:$AO,"F",FUNDAÇÕES!$AQ:$AQ) -> 264.32208 | G11: =SUMIF(FUNDAÇÕES!$AO:$AO,"F",FUNDAÇÕES!$I:$I) -> 5.89 | H11: 4.316 | I11: 522 | J11: 10.2 | L11: =E11*$N$4 -> 290.75429 | P11: =IF(ISNUMBER(H11),H11-D11,"") -> 0.0005 | Q11: =IF(ISNUMBER(I11),I11-F11,"") -> 257.67792 | R11: =IF(ISNUMBER(J11),J11-G11,"") -> 4.31 | T11: =SUMIF(FUNDAÇÕES!$AO:$AO,"F",FUNDAÇÕES!$AR:$AR) -> 4.3155 | U11: Ensoleiramento LMFelev 3.15x2.74x0.50 (ES0501).
B12: 20.2.1.1.3 | C12: Vigas de Equilíbrio e Vigas Lintel de Fundação
B13: 20.2.1.1.3.1 | C13: (Zona B) | D13: =SUMIF('VIGAS DE FUNDAÇÃO'!$AO:$AO,"B",'VIGAS DE FUNDAÇÃO'!$G:$G) -> 1.828 | E13: =SUMIF('VIGAS DE FUNDAÇÃO'!$AO:$AO,"B",'VIGAS DE FUNDAÇÃO'!$AP:$AP) -> 395.322 | F13: =E13+SUMIF('VIGAS DE FUNDAÇÃO'!$AO:$AO,"B",'VIGAS DE FUNDAÇÃO'!$AQ:$AQ) -> 395.322 | G13: =SUMIF('VIGAS DE FUNDAÇÃO'!$AO:$AO,"B",'VIGAS DE FUNDAÇÃO'!$I:$I) -> 9.14 | H13: 1.84 | I13: 223 | J13: 16.42 | L13: =E13*$N$4 -> 434.8542 | P13: =IF(ISNUMBER(H13),H13-D13,"") -> 0.012 | Q13: =IF(ISNUMBER(I13),I13-F13,"") -> -172.322 | R13: =IF(ISNUMBER(J13),J13-G13,"") -> 7.28 | T13: =SUMIF('VIGAS DE FUNDAÇÃO'!$AO:$AO,"B",'VIGAS DE FUNDAÇÃO'!$AR:$AR) -> 1.828 | U13: VE1 x2 (ES0201).
B14: 20.2.1.1.3.2 | C14: (Zona C) | D14: =SUMIF('VIGAS DE FUNDAÇÃO'!$AO:$AO,"C",'VIGAS DE FUNDAÇÃO'!$G:$G) -> 5.2944 | E14: =SUMIF('VIGAS DE FUNDAÇÃO'!$AO:$AO,"C",'VIGAS DE FUNDAÇÃO'!$AP:$AP) -> 768.7063 | F14: =E14+SUMIF('VIGAS DE FUNDAÇÃO'!$AO:$AO,"C",'VIGAS DE FUNDAÇÃO'!$AQ:$AQ) -> 768.7063 | G14: =SUMIF('VIGAS DE FUNDAÇÃO'!$AO:$AO,"C",'VIGAS DE FUNDAÇÃO'!$I:$I) -> 44.12 | H14: 5.371 | I14: 650 | J14: 47.94 | L14: =E14*$N$4 -> 845.57693 | P14: =IF(ISNUMBER(H14),H14-D14,"") -> 0.0766 | Q14: =IF(ISNUMBER(I14),I14-F14,"") -> -118.7063 | R14: =IF(ISNUMBER(J14),J14-G14,"") -> 3.82 | T14: =SUMIF('VIGAS DE FUNDAÇÃO'!$AO:$AO,"C",'VIGAS DE FUNDAÇÃO'!$AR:$AR) -> 5.2944 | U14: VL1 - 11 tramos (ES0302).
B15: 20.2.1.2.1 | C15: Limpeza
B16: 20.2.1.2.1.1 | C16: (Zona A) | D16: =SUMIF('BETÃO DE LIMPEZA '!$AO:$AO,"A",'BETÃO DE LIMPEZA '!$I:$I) -> 22.265 | E16: - | G16: - | H16: 22.265 | I16: - | J16: - | P16: =IF(ISNUMBER(H16),H16-D16,"") -> 0 | U16: Área (m2) com sobrelargura 0.05 m/lado.
B17: 20.2.1.2.1.2 | C17: (Zona B) | D17: =SUMIF('BETÃO DE LIMPEZA '!$AO:$AO,"B",'BETÃO DE LIMPEZA '!$I:$I) -> 16.45 | E17: - | G17: - | H17: 16.48 | I17: - | J17: - | P17: =IF(ISNUMBER(H17),H17-D17,"") -> 0.03 | U17: Inclui VE1; exclui S5 sobre poços PF1 (PB7, PB9).
B18: 20.2.1.2.1.3 | C18: (Zona C) | D18: =SUMIF('BETÃO DE LIMPEZA '!$AO:$AO,"C",'BETÃO DE LIMPEZA '!$I:$I) -> 50.655598 | E18: - | G18: - | H18: 49.688 | I18: - | J18: - | P18: =IF(ISNUMBER(H18),H18-D18,"") -> -0.967598 | U18: Inclui VL1.
B19: 20.2.1.2.1.4 | C19: (Zona D) | D19: =SUMIF('BETÃO DE LIMPEZA '!$AO:$AO,"D",'BETÃO DE LIMPEZA '!$I:$I) -> 1.44 | E19: - | G19: - | H19: 1.21 | I19: - | J19: - | P19: =IF(ISNUMBER(H19),H19-D19,"") -> -0.23 | U19: SE1.
B20: 20.2.1.2.1.5 | C20: (Zona E) | D20: =SUMIF('BETÃO DE LIMPEZA '!$AO:$AO,"E",'BETÃO DE LIMPEZA '!$I:$I) -> 19.46575 | E20: - | G20: - | H20: 19.14 | I20: - | J20: - | P20: =IF(ISNUMBER(H20),H20-D20,"") -> -0.32575 | U20: SMS1.1-1.4.
B21: 20.2.1.2.1.6 | C21: (Zona F) | D21: =SUMIF('BETÃO DE LIMPEZA '!$AO:$AO,"F",'BETÃO DE LIMPEZA '!$I:$I) -> 9.23 | E21: - | G21: - | H21: 9.07 | I21: - | J21: - | P21: =IF(ISNUMBER(H21),H21-D21,"") -> -0.16 | U21: LMFelev.
B22: 20.2.1.3.1 | C22: Poços de Fundação
B23: 20.2.1.3.1.1 | C23: (Zona B) | D23: =SUMIF('POÇOS DE FUNDAÇÃO'!$AO:$AO,"B",'POÇOS DE FUNDAÇÃO'!$G:$G) -> 20.35752 | E23: - | G23: - | H23: 25.34 | I23: - | J23: - | P23: =IF(ISNUMBER(H23),H23-D23,"") -> 4.9824796 | T23: =SUMIF('POÇOS DE FUNDAÇÃO'!$AO:$AO,"B",'POÇOS DE FUNDAÇÃO'!$AR:$AR) -> 20.3574 | U23: MQT 25.34 m3 vs geometria 4xπx0.6²x4.50 = 20.36 m3 (ver DISCREPÂNCIAS).
B24: 20.3.1.2.1.1 | C24: Muros de Suporte de Betão Armado à Vista
B25: 20.3.1.2.1.1.1 | C25: (Zona E) | D25: =SUMIF('PAREDE BETÃO'!$AO:$AO,"E",'PAREDE BETÃO'!$G:$G) -> 5.256375 | E25: =SUMIF('PAREDE BETÃO'!$AO:$AO,"E",'PAREDE BETÃO'!$AP:$AP) -> 806.16231 | F25: =E25+SUMIF('PAREDE BETÃO'!$AO:$AO,"E",'PAREDE BETÃO'!$AQ:$AQ) -> 806.16231 | G25: =SUMIF('PAREDE BETÃO'!$AO:$AO,"E",'PAREDE BETÃO'!$I:$I) -> 42.051 | H25: 5.257 | I25: 694 | J25: 44.1588 | L25: =E25*$N$4 -> 886.77854 | P25: =IF(ISNUMBER(H25),H25-D25,"") -> 0.000625 | Q25: =IF(ISNUMBER(I25),I25-F25,"") -> -112.16231 | R25: =IF(ISNUMBER(J25),J25-G25,"") -> 2.1078 | T25: =SUMIF('PAREDE BETÃO'!$AO:$AO,"E",'PAREDE BETÃO'!$AR:$AR) -> 5.2564 | U25: MS1.1-MS1.4: área de face do modelo x 0.25; cofragem 2 faces.
B26: 20.4.1.1.1.1 | C26: Lajes Maciças
B27: 20.4.1.1.1.1.1 | C27: (Zona A) | D27: =SUMIF(LAJES!$AO:$AO,"A",LAJES!$G:$G) -> 10.18438 | E27: =SUMIF(LAJES!$AO:$AO,"A",LAJES!$AP:$AP) -> 1418.0981 | F27: =E27+SUMIF(LAJES!$AO:$AO,"A",LAJES!$AQ:$AQ) -> 1418.0981 | G27: =SUMIF(LAJES!$AO:$AO,"A",LAJES!$I:$I) -> 50.9219 | H27: 10.17 | I27: 1846 | J27: 53.39 | L27: =E27*$N$4 -> 1559.9079 | P27: =IF(ISNUMBER(H27),H27-D27,"") -> -0.01438 | Q27: =IF(ISNUMBER(I27),I27-F27,"") -> 427.90189 | R27: =IF(ISNUMBER(J27),J27-G27,"") -> 2.4681 | T27: =SUMIF(LAJES!$AO:$AO,"A",LAJES!$AR:$AR) -> 10.1844
B28: 20.4.1.1.1.1.2 | C28: (Zona B) | D28: =SUMIF(LAJES!$AO:$AO,"B",LAJES!$G:$G) -> 21.70084 | E28: =SUMIF(LAJES!$AO:$AO,"B",LAJES!$AP:$AP) -> 4119.1851 | F28: =E28+SUMIF(LAJES!$AO:$AO,"B",LAJES!$AQ:$AQ) -> 4119.1851 | G28: =SUMIF(LAJES!$AO:$AO,"B",LAJES!$I:$I) -> 108.5042 | H28: 21.71 | I28: 4299 | J28: 113.98 | L28: =E28*$N$4 -> 4531.1036 | P28: =IF(ISNUMBER(H28),H28-D28,"") -> 0.00916 | Q28: =IF(ISNUMBER(I28),I28-F28,"") -> 179.81486 | R28: =IF(ISNUMBER(J28),J28-G28,"") -> 5.4758 | T28: =SUMIF(LAJES!$AO:$AO,"B",LAJES!$AR:$AR) -> 21.7008
B29: 20.4.1.1.1.1.3 | C29: (Zona C) | D29: =SUMIF(LAJES!$AO:$AO,"C",LAJES!$G:$G) -> 5.51284 | E29: =SUMIF(LAJES!$AO:$AO,"C",LAJES!$AP:$AP) -> 512.87116 | F29: =E29+SUMIF(LAJES!$AO:$AO,"C",LAJES!$AQ:$AQ) -> 512.87116 | G29: =SUMIF(LAJES!$AO:$AO,"C",LAJES!$I:$I) -> 27.5642 | H29: 5.515 | I29: 1092 | J29: 28.95 | L29: =E29*$N$4 -> 564.15828 | P29: =IF(ISNUMBER(H29),H29-D29,"") -> 0.00216 | Q29: =IF(ISNUMBER(I29),I29-F29,"") -> 579.12884 | R29: =IF(ISNUMBER(J29),J29-G29,"") -> 1.3858 | T29: =SUMIF(LAJES!$AO:$AO,"C",LAJES!$AR:$AR) -> 5.5128
B30: 20.4.1.1.1.1.4 | C30: (Zona D) | D30: =SUMIF(LAJES!$AO:$AO,"D",LAJES!$G:$G) -> 0.818 | E30: =SUMIF(LAJES!$AO:$AO,"D",LAJES!$AP:$AP) -> 55.784533 | F30: =E30+SUMIF(LAJES!$AO:$AO,"D",LAJES!$AQ:$AQ) -> 55.784533 | G30: =SUMIF(LAJES!$AO:$AO,"D",LAJES!$I:$I) -> 5.29 | H30: 0.818 | I30: 162 | J30: 4.29 | L30: =E30*$N$4 -> 61.362987 | P30: =IF(ISNUMBER(H30),H30-D30,"") -> 0 | Q30: =IF(ISNUMBER(I30),I30-F30,"") -> 106.21547 | R30: =IF(ISNUMBER(J30),J30-G30,"") -> -1 | T30: =SUMIF(LAJES!$AO:$AO,"D",LAJES!$AR:$AR) -> 0.818
B31: 20.4.1.1.1.1.5 | C31: (Zona F) | D31: =SUMIF(LAJES!$AO:$AO,"F",LAJES!$G:$G) -> 0.6897 | E31: =SUMIF(LAJES!$AO:$AO,"F",LAJES!$AP:$AP) -> 75.61952 | F31: =E31+SUMIF(LAJES!$AO:$AO,"F",LAJES!$AQ:$AQ) -> 75.61952 | G31: =SUMIF(LAJES!$AO:$AO,"F",LAJES!$I:$I) -> 3.4485 | H31: 0.69 | I31: 137 | J31: 3.62 | L31: =E31*$N$4 -> 83.181472 | P31: =IF(ISNUMBER(H31),H31-D31,"") -> 0.0003 | Q31: =IF(ISNUMBER(I31),I31-F31,"") -> 61.38048 | R31: =IF(ISNUMBER(J31),J31-G31,"") -> 0.1715 | T31: =SUMIF(LAJES!$AO:$AO,"F",LAJES!$AR:$AR) -> 0.6897
B32: 20.4.1.1.2 | C32: Muretes
B33: 6.4.1.1.2.1 | C33: (Zona F) | D33: =SUMIF(MURETES!$AO:$AO,"F",MURETES!$G:$G) -> 0.2302 | E33: =SUMIF(MURETES!$AO:$AO,"F",MURETES!$AP:$AP) -> 35.118929 | F33: =E33+SUMIF(MURETES!$AO:$AO,"F",MURETES!$AQ:$AQ) -> 35.118929 | G33: =SUMIF(MURETES!$AO:$AO,"F",MURETES!$I:$I) -> 3.0693333 | H33: 0.23 | I33: 46 | J33: 2.9 | L33: =E33*$N$4 -> 38.630822 | P33: =IF(ISNUMBER(H33),H33-D33,"") -> -0.0002 | Q33: =IF(ISNUMBER(I33),I33-F33,"") -> 10.881071 | R33: =IF(ISNUMBER(J33),J33-G33,"") -> -0.16933333 | T33: =SUMIF(MURETES!$AO:$AO,"F",MURETES!$AR:$AR) -> 0.2302 | U33: Código do artigo "6.4.1.1.2.1" mantido do original (provável 20.4.1.1.2.1).
B34: 20.4.1.1.3 | C34: Paredes
B35: 20.4.1.1.3.1 | C35: (Zona F) | D35: =SUMIF(PAREDES!$AO:$AO,"F1",PAREDES!$G:$G) -> 12.06235 | E35: =SUMIF(PAREDES!$AO:$AO,"F1",PAREDES!$AP:$AP) -> 1070.6608 | F35: =E35+SUMIF(PAREDES!$AO:$AO,"F1",PAREDES!$AQ:$AQ) -> 1070.6608 | G35: =SUMIF(PAREDES!$AO:$AO,"F1",PAREDES!$I:$I) -> 96.4988 | H35: 12.06 | I35: 2388 | J35: 126.63 | L35: =E35*$N$4 -> 1177.7269 | P35: =IF(ISNUMBER(H35),H35-D35,"") -> -0.00235 | Q35: =IF(ISNUMBER(I35),I35-F35,"") -> 1317.3392 | R35: =IF(ISNUMBER(J35),J35-G35,"") -> 30.1312 | T35: =SUMIF(PAREDES!$AO:$AO,"F1",PAREDES!$AR:$AR) -> 12.0624 | U35: NUCelev 0.25 x2.
B36: 20.4.1.1.3.2 | C36: (Zona F) | D36: =SUMIF(PAREDES!$AO:$AO,"F2",PAREDES!$G:$G) -> 1.02588 | E36: =SUMIF(PAREDES!$AO:$AO,"F2",PAREDES!$AP:$AP) -> 173.15995 | F36: =E36+SUMIF(PAREDES!$AO:$AO,"F2",PAREDES!$AQ:$AQ) -> 173.15995 | G36: =SUMIF(PAREDES!$AO:$AO,"F2",PAREDES!$I:$I) -> 6.8392 | H36: 1.026 | I36: 203 | J36: 10.77 | L36: =E36*$N$4 -> 190.47594 | P36: =IF(ISNUMBER(H36),H36-D36,"") -> 0.00012 | Q36: =IF(ISNUMBER(I36),I36-F36,"") -> 29.840054 | R36: =IF(ISNUMBER(J36),J36-G36,"") -> 3.9308 | T36: =SUMIF(PAREDES!$AO:$AO,"F2",PAREDES!$AR:$AR) -> 1.0259 | U36: NUCelev 0.15 (cofragem 1 face).
B37: 20.4.1.1.4 | C37: Pilares
B38: 20.4.1.1.4.1 | C38: (Zona A) | D38: =SUMIF(PILARES!$AO:$AO,"A",PILARES!$G:$G) -> 4.450325 | E38: =SUMIF(PILARES!$AO:$AO,"A",PILARES!$AP:$AP) -> 1043.7505 | F38: =E38+SUMIF(PILARES!$AO:$AO,"A",PILARES!$AQ:$AQ) -> 1152.2545 | G38: =SUMIF(PILARES!$AO:$AO,"A",PILARES!$I:$I) -> 71.35 | H38: 4.533 | I38: 1072 | J38: 61.88 | L38: =E38*$N$4 -> 1148.1255 | P38: =IF(ISNUMBER(H38),H38-D38,"") -> 0.082675 | Q38: =IF(ISNUMBER(I38),I38-F38,"") -> -80.25448 | R38: =IF(ISNUMBER(J38),J38-G38,"") -> -9.47 | T38: =SUMIF(PILARES!$AO:$AO,"A",PILARES!$AR:$AR) -> 4.4502 | U38: Exclui "Pexistente" (pilar existente modelado).
B39: 20.4.1.1.4.2 | C39: (Zona B) | D39: =SUMIF(PILARES!$AO:$AO,"B",PILARES!$G:$G) -> 2.9947825 | E39: =SUMIF(PILARES!$AO:$AO,"B",PILARES!$AP:$AP) -> 738.86079 | F39: =E39+SUMIF(PILARES!$AO:$AO,"B",PILARES!$AQ:$AQ) -> 798.04479 | G39: =SUMIF(PILARES!$AO:$AO,"B",PILARES!$I:$I) -> 45.925 | H39: 2.994 | I39: 708 | J39: 40.87 | L39: =E39*$N$4 -> 812.74687 | P39: =IF(ISNUMBER(H39),H39-D39,"") -> -0.0007825 | Q39: =IF(ISNUMBER(I39),I39-F39,"") -> -90.044792 | R39: =IF(ISNUMBER(J39),J39-G39,"") -> -5.055 | T39: =SUMIF(PILARES!$AO:$AO,"B",PILARES!$AR:$AR) -> 2.9344
B40: 20.4.1.1.4.3 | C40: (Zona C) | D40: =SUMIF(PILARES!$AO:$AO,"C",PILARES!$G:$G) -> 4.70376 | E40: =SUMIF(PILARES!$AO:$AO,"C",PILARES!$AP:$AP) -> 1175.7199 | F40: =E40+SUMIF(PILARES!$AO:$AO,"C",PILARES!$AQ:$AQ) -> 1175.7199 | G40: =SUMIF(PILARES!$AO:$AO,"C",PILARES!$I:$I) -> 64.758 | H40: 4.751 | I40: 1124 | J40: 64.85 | L40: =E40*$N$4 -> 1293.2919 | P40: =IF(ISNUMBER(H40),H40-D40,"") -> 0.04724 | Q40: =IF(ISNUMBER(I40),I40-F40,"") -> -51.719893 | R40: =IF(ISNUMBER(J40),J40-G40,"") -> 0.092 | T40: =SUMIF(PILARES!$AO:$AO,"C",PILARES!$AR:$AR) -> 4.704
...

Sheet BETÃO DE LIMPEZA 
E1: MEDIÇÕES DE BETÃO ARMADO | S1: Obra: | T1: 050.24 - LAR DE S. JORGE, GMR | W1: Executou:
S2: Local: | T2: Pevidém, Guimarães | W2: Data: | X2: =TODAY() -> 46325
A4: ARTº | B4: Designação | C4: BETÃO | I4: ÁREA | K4: AÇO SEM EMPALMES | R4: DIÃMETROS | AA4: AÇO EMPALMES | AF4: DIÃMETROS | AN4: REDE ELECTROS. | AO4: ZONA | AP4: AÇO s/ EMP. (kg) | AQ4: AÇO EMP. (kg) | AR4: BETÃO MODELO BIM (m3) | AS4: FONTE / OBSERVAÇÕES | AT4: ESTADO
C5: Nº | D5: C (BX) | E5: L (BY) | F5: H | G5: BETÃO LIMPEZA M3 | I5: (m2) | K5: Designação | L5: L | M5: P | N5: Nº (PI) | O5: QUANT. | P5: Ø | Q5: COMP. | R5: Ø 6 | S5: Ø 8 | T5: Ø 10 | U5: Ø 12 | V5: Ø 16 | W5: Ø 20 | X5: Ø 25 | Y5: Ø 32 | AA5: Nº (PI) | AB5: nº varões | AC5: nº empalmes | AD5: ɸ | AE5: Ø | AF5: Ø 6 | AG5: Ø 8 | AH5: Ø 10 | AI5: Ø 12 | AJ5: Ø 16 | AK5: Ø 20 | AL5: Ø 25 | AM5: Ø 32 | AN5: (kg)
B6: ZONA A - BETÃO DE LIMPEZA C16/20 (e=0.10; sobrelargura 0.05 m por lado)
B7: S6 (PA1, PA2) | C7: 1 | D7: =2.4+2*0.05 -> 2.5 | E7: =2.8+2*0.05 -> 2.9 | F7: 0.1 | G7: =C7*D7*E7*F7 -> 0.725 | I7: =C7*D7*E7 -> 7.25 | R7: =IF(P7=6,N7*O7*Q7*0.222*1,IF(P7>6,"",IF(P7<6,""))) | S7: =IF(P7=8,N7*O7*Q7*0.395*1,IF(P7>8,"",IF(P7<8,""))) | T7: =IF(P7=10,N7*O7*Q7*0.617*1,IF(P7>10,"",IF(P7<10,""))) | U7: =IF(P7=12,N7*O7*Q7*0.888*1,IF(P7>12,"",IF(P7<12,""))) | V7: =IF(P7=16,N7*O7*Q7*1.578*1,IF(P7>16,"",IF(P7<16,""))) | W7: =IF(P7=20,N7*O7*Q7*2.466*1,IF(P7>20,"",IF(P7<20,""))) | X7: =IF(P7=25,N7*O7*Q7*3.853*1,IF(P7>25,"",IF(P7<25,""))) | Y7: =IF(P7=32,N7*O7*Q7*6.313*1,IF(P7>32,"",IF(P7<32,""))) | AA7: =IF(AC7>0,N7,"") | AB7: =IF(AC7>0,O7,"") | AE7: =IF(AC7>0,P7,"") | AF7: =IF(AE7=6,AA7*AB7*AC7*AD7*(AE7/1000)*0.222*1,IF(AE7>6,"",IF(AE7<6,""))) | AG7: =IF(AE7=8,AA7*AB7*AC7*AD7*(AE7/1000)*0.395*1,IF(AE7>8,"",IF(AE7<8,""))) | AH7: =IF(AE7=10,AA7*AB7*AC7*AD7*(AE7/1000)*0.617*1,IF(AE7>10,"",IF(AE7<10,""))) | AI7: =IF(AE7=12,AA7*AB7*AC7*AD7*(AE7/1000)*0.888*1,IF(AE7>12,"",IF(AE7<12,""))) | AJ7: =IF(AE7=16,AA7*AB7*AC7*AD7*(AE7/1000)*1.578*1,IF(AE7>16,"",IF(AE7<16,""))) | AK7: =IF(AE7=20,AA7*AB7*AC7*AD7*(AE7/1000)*2.466*1,IF(AE7>20,"",IF(AE7<20,""))) | AL7: =IF(AE7=25,AA7*AB7*AC7*AD7*(AE7/1000)*3.853*1,IF(AE7>25,"",IF(AE7<25,""))) | AM7: =IF(AE7=32,AA7*AB7*AC7*AD7*(AE7/1000)*6.313*1,IF(AE7>32,"",IF(AE7<32,""))) | AO7: A | AP7: =SUM(R7:Y7)+SUM(AN7) -> 0 | AQ7: =SUM(AF7:AM7) -> 0 | AS7: ES0101 pormenor tipo de sapatas (5 cm por lado, 10 cm) | AT7: Calculado
B8: S7 (PA4, PA5) | C8: 1 | D8: =1.5+2*0.05 -> 1.6 | E8: =2.7+2*0.05 -> 2.8 | F8: 0.1 | G8: =C8*D8*E8*F8 -> 0.448 | I8: =C8*D8*E8 -> 4.48 | R8: =IF(P8=6,N8*O8*Q8*0.222*1,IF(P8>6,"",IF(P8<6,""))) | S8: =IF(P8=8,N8*O8*Q8*0.395*1,IF(P8>8,"",IF(P8<8,""))) | T8: =IF(P8=10,N8*O8*Q8*0.617*1,IF(P8>10,"",IF(P8<10,""))) | U8: =IF(P8=12,N8*O8*Q8*0.888*1,IF(P8>12,"",IF(P8<12,""))) | V8: =IF(P8=16,N8*O8*Q8*1.578*1,IF(P8>16,"",IF(P8<16,""))) | W8: =IF(P8=20,N8*O8*Q8*2.466*1,IF(P8>20,"",IF(P8<20,""))) | X8: =IF(P8=25,N8*O8*Q8*3.853*1,IF(P8>25,"",IF(P8<25,""))) | Y8: =IF(P8=32,N8*O8*Q8*6.313*1,IF(P8>32,"",IF(P8<32,""))) | AA8: =IF(AC8>0,N8,"") | AB8: =IF(AC8>0,O8,"") | AE8: =IF(AC8>0,P8,"") | AF8: =IF(AE8=6,AA8*AB8*AC8*AD8*(AE8/1000)*0.222*1,IF(AE8>6,"",IF(AE8<6,""))) | AG8: =IF(AE8=8,AA8*AB8*AC8*AD8*(AE8/1000)*0.395*1,IF(AE8>8,"",IF(AE8<8,""))) | AH8: =IF(AE8=10,AA8*AB8*AC8*AD8*(AE8/1000)*0.617*1,IF(AE8>10,"",IF(AE8<10,""))) | AI8: =IF(AE8=12,AA8*AB8*AC8*AD8*(AE8/1000)*0.888*1,IF(AE8>12,"",IF(AE8<12,""))) | AJ8: =IF(AE8=16,AA8*AB8*AC8*AD8*(AE8/1000)*1.578*1,IF(AE8>16,"",IF(AE8<16,""))) | AK8: =IF(AE8=20,AA8*AB8*AC8*AD8*(AE8/1000)*2.466*1,IF(AE8>20,"",IF(AE8<20,""))) | AL8: =IF(AE8=25,AA8*AB8*AC8*AD8*(AE8/1000)*3.853*1,IF(AE8>25,"",IF(AE8<25,""))) | AM8: =IF(AE8=32,AA8*AB8*AC8*AD8*(AE8/1000)*6.313*1,IF(AE8>32,"",IF(AE8<32,""))) | AO8: A | AP8: =SUM(R8:Y8)+SUM(AN8) -> 0 | AQ8: =SUM(AF8:AM8) -> 0 | AS8: ES0101 pormenor tipo de sapatas (5 cm por lado, 10 cm) | AT8: Calculado
B9: S8 (PA7, PA8) | C9: 1 | D9: =1+2*0.05 -> 1.1 | E9: =2.35+2*0.05 -> 2.45 | F9: 0.1 | G9: =C9*D9*E9*F9 -> 0.2695 | I9: =C9*D9*E9 -> 2.695 | R9: =IF(P9=6,N9*O9*Q9*0.222*1,IF(P9>6,"",IF(P9<6,""))) | S9: =IF(P9=8,N9*O9*Q9*0.395*1,IF(P9>8,"",IF(P9<8,""))) | T9: =IF(P9=10,N9*O9*Q9*0.617*1,IF(P9>10,"",IF(P9<10,""))) | U9: =IF(P9=12,N9*O9*Q9*0.888*1,IF(P9>12,"",IF(P9<12,""))) | V9: =IF(P9=16,N9*O9*Q9*1.578*1,IF(P9>16,"",IF(P9<16,""))) | W9: =IF(P9=20,N9*O9*Q9*2.466*1,IF(P9>20,"",IF(P9<20,""))) | X9: =IF(P9=25,N9*O9*Q9*3.853*1,IF(P9>25,"",IF(P9<25,""))) | Y9: =IF(P9=32,N9*O9*Q9*6.313*1,IF(P9>32,"",IF(P9<32,""))) | AA9: =IF(AC9>0,N9,"") | AB9: =IF(AC9>0,O9,"") | AE9: =IF(AC9>0,P9,"") | AF9: =IF(AE9=6,AA9*AB9*AC9*AD9*(AE9/1000)*0.222*1,IF(AE9>6,"",IF(AE9<6,""))) | AG9: =IF(AE9=8,AA9*AB9*AC9*AD9*(AE9/1000)*0.395*1,IF(AE9>8,"",IF(AE9<8,""))) | AH9: =IF(AE9=10,AA9*AB9*AC9*AD9*(AE9/1000)*0.617*1,IF(AE9>10,"",IF(AE9<10,""))) | AI9: =IF(AE9=12,AA9*AB9*AC9*AD9*(AE9/1000)*0.888*1,IF(AE9>12,"",IF(AE9<12,""))) | AJ9: =IF(AE9=16,AA9*AB9*AC9*AD9*(AE9/1000)*1.578*1,IF(AE9>16,"",IF(AE9<16,""))) | AK9: =IF(AE9=20,AA9*AB9*AC9*AD9*(AE9/1000)*2.466*1,IF(AE9>20,"",IF(AE9<20,""))) | AL9: =IF(AE9=25,AA9*AB9*AC9*AD9*(AE9/1000)*3.853*1,IF(AE9>25,"",IF(AE9<25,""))) | AM9: =IF(AE9=32,AA9*AB9*AC9*AD9*(AE9/1000)*6.313*1,IF(AE9>32,"",IF(AE9<32,""))) | AO9: A | AP9: =SUM(R9:Y9)+SUM(AN9) -> 0 | AQ9: =SUM(AF9:AM9) -> 0 | AS9: ES0101 pormenor tipo de sapatas (5 cm por lado, 10 cm) | AT9: Calculado
B10: S9 (PA9) | C10: 1 | D10: =1.3+2*0.05 -> 1.4 | E10: =1.3+2*0.05 -> 1.4 | F10: 0.1 | G10: =C10*D10*E10*F10 -> 0.196 | I10: =C10*D10*E10 -> 1.96 | R10: =IF(P10=6,N10*O10*Q10*0.222*1,IF(P10>6,"",IF(P10<6,""))) | S10: =IF(P10=8,N10*O10*Q10*0.395*1,IF(P10>8,"",IF(P10<8,""))) | T10: =IF(P10=10,N10*O10*Q10*0.617*1,IF(P10>10,"",IF(P10<10,""))) | U10: =IF(P10=12,N10*O10*Q10*0.888*1,IF(P10>12,"",IF(P10<12,""))) | V10: =IF(P10=16,N10*O10*Q10*1.578*1,IF(P10>16,"",IF(P10<16,""))) | W10: =IF(P10=20,N10*O10*Q10*2.466*1,IF(P10>20,"",IF(P10<20,""))) | X10: =IF(P10=25,N10*O10*Q10*3.853*1,IF(P10>25,"",IF(P10<25,""))) | Y10: =IF(P10=32,N10*O10*Q10*6.313*1,IF(P10>32,"",IF(P10<32,""))) | AA10: =IF(AC10>0,N10,"") | AB10: =IF(AC10>0,O10,"") | AE10: =IF(AC10>0,P10,"") | AF10: =IF(AE10=6,AA10*AB10*AC10*AD10*(AE10/1000)*0.222*1,IF(AE10>6,"",IF(AE10<6,""))) | AG10: =IF(AE10=8,AA10*AB10*AC10*AD10*(AE10/1000)*0.395*1,IF(AE10>8,"",IF(AE10<8,""))) | AH10: =IF(AE10=10,AA10*AB10*AC10*AD10*(AE10/1000)*0.617*1,IF(AE10>10,"",IF(AE10<10,""))) | AI10: =IF(AE10=12,AA10*AB10*AC10*AD10*(AE10/1000)*0.888*1,IF(AE10>12,"",IF(AE10<12,""))) | AJ10: =IF(AE10=16,AA10*AB10*AC10*AD10*(AE10/1000)*1.578*1,IF(AE10>16,"",IF(AE10<16,""))) | AK10: =IF(AE10=20,AA10*AB10*AC10*AD10*(AE10/1000)*2.466*1,IF(AE10>20,"",IF(AE10<20,""))) | AL10: =IF(AE10=25,AA10*AB10*AC10*AD10*(AE10/1000)*3.853*1,IF(AE10>25,"",IF(AE10<25,""))) | AM10: =IF(AE10=32,AA10*AB10*AC10*AD10*(AE10/1000)*6.313*1,IF(AE10>32,"",IF(AE10<32,""))) | AO10: A | AP10: =SUM(R10:Y10)+SUM(AN10) -> 0 | AQ10: =SUM(AF10:AM10) -> 0 | AS10: ES0101 pormenor tipo de sapatas (5 cm por lado, 10 cm) | AT10: Calculado
B11: S10 (PA10) | C11: 1 | D11: =1.5+2*0.05 -> 1.6 | E11: =1.3+2*0.05 -> 1.4 | F11: 0.1 | G11: =C11*D11*E11*F11 -> 0.224 | I11: =C11*D11*E11 -> 2.24 | R11: =IF(P11=6,N11*O11*Q11*0.222*1,IF(P11>6,"",IF(P11<6,""))) | S11: =IF(P11=8,N11*O11*Q11*0.395*1,IF(P11>8,"",IF(P11<8,""))) | T11: =IF(P11=10,N11*O11*Q11*0.617*1,IF(P11>10,"",IF(P11<10,""))) | U11: =IF(P11=12,N11*O11*Q11*0.888*1,IF(P11>12,"",IF(P11<12,""))) | V11: =IF(P11=16,N11*O11*Q11*1.578*1,IF(P11>16,"",IF(P11<16,""))) | W11: =IF(P11=20,N11*O11*Q11*2.466*1,IF(P11>20,"",IF(P11<20,""))) | X11: =IF(P11=25,N11*O11*Q11*3.853*1,IF(P11>25,"",IF(P11<25,""))) | Y11: =IF(P11=32,N11*O11*Q11*6.313*1,IF(P11>32,"",IF(P11<32,""))) | AA11: =IF(AC11>0,N11,"") | AB11: =IF(AC11>0,O11,"") | AE11: =IF(AC11>0,P11,"") | AF11: =IF(AE11=6,AA11*AB11*AC11*AD11*(AE11/1000)*0.222*1,IF(AE11>6,"",IF(AE11<6,""))) | AG11: =IF(AE11=8,AA11*AB11*AC11*AD11*(AE11/1000)*0.395*1,IF(AE11>8,"",IF(AE11<8,""))) | AH11: =IF(AE11=10,AA11*AB11*AC11*AD11*(AE11/1000)*0.617*1,IF(AE11>10,"",IF(AE11<10,""))) | AI11: =IF(AE11=12,AA11*AB11*AC11*AD11*(AE11/1000)*0.888*1,IF(AE11>12,"",IF(AE11<12,""))) | AJ11: =IF(AE11=16,AA11*AB11*AC11*AD11*(AE11/1000)*1.578*1,IF(AE11>16,"",IF(AE11<16,""))) | AK11: =IF(AE11=20,AA11*AB11*AC11*AD11*(AE11/1000)*2.466*1,IF(AE11>20,"",IF(AE11<20,""))) | AL11: =IF(AE11=25,AA11*AB11*AC11*AD11*(AE11/1000)*3.853*1,IF(AE11>25,"",IF(AE11<25,""))) | AM11: =IF(AE11=32,AA11*AB11*AC11*AD11*(AE11/1000)*6.313*1,IF(AE11>32,"",IF(AE11<32,""))) | AO11: A | AP11: =SUM(R11:Y11)+SUM(AN11) -> 0 | AQ11: =SUM(AF11:AM11) -> 0 | AS11: ES0101 pormenor tipo de sapatas (5 cm por lado, 10 cm) | AT11: Calculado
B12: S11 (PA11, PA12) | C12: 1 | D12: =2.5+2*0.05 -> 2.6 | E12: =1.3+2*0.05 -> 1.4 | F12: 0.1 | G12: =C12*D12*E12*F12 -> 0.364 | I12: =C12*D12*E12 -> 3.64 | R12: =IF(P12=6,N12*O12*Q12*0.222*1,IF(P12>6,"",IF(P12<6,""))) | S12: =IF(P12=8,N12*O12*Q12*0.395*1,IF(P12>8,"",IF(P12<8,""))) | T12: =IF(P12=10,N12*O12*Q12*0.617*1,IF(P12>10,"",IF(P12<10,""))) | U12: =IF(P12=12,N12*O12*Q12*0.888*1,IF(P12>12,"",IF(P12<12,""))) | V12: =IF(P12=16,N12*O12*Q12*1.578*1,IF(P12>16,"",IF(P12<16,""))) | W12: =IF(P12=20,N12*O12*Q12*2.466*1,IF(P12>20,"",IF(P12<20,""))) | X12: =IF(P12=25,N12*O12*Q12*3.853*1,IF(P12>25,"",IF(P12<25,""))) | Y12: =IF(P12=32,N12*O12*Q12*6.313*1,IF(P12>32,"",IF(P12<32,""))) | AA12: =IF(AC12>0,N12,"") | AB12: =IF(AC12>0,O12,"") | AE12: =IF(AC12>0,P12,"") | AF12: =IF(AE12=6,AA12*AB12*AC12*AD12*(AE12/1000)*0.222*1,IF(AE12>6,"",IF(AE12<6,""))) | AG12: =IF(AE12=8,AA12*AB12*AC12*AD12*(AE12/1000)*0.395*1,IF(AE12>8,"",IF(AE12<8,""))) | AH12: =IF(AE12=10,AA12*AB12*AC12*AD12*(AE12/1000)*0.617*1,IF(AE12>10,"",IF(AE12<10,""))) | AI12: =IF(AE12=12,AA12*AB12*AC12*AD12*(AE12/1000)*0.888*1,IF(AE12>12,"",IF(AE12<12,""))) | AJ12: =IF(AE12=16,AA12*AB12*AC12*AD12*(AE12/1000)*1.578*1,IF(AE12>16,"",IF(AE12<16,""))) | AK12: =IF(AE12=20,AA12*AB12*AC12*AD12*(AE12/1000)*2.466*1,IF(AE12>20,"",IF(AE12<20,""))) | AL12: =IF(AE12=25,AA12*AB12*AC12*AD12*(AE12/1000)*3.853*1,IF(AE12>25,"",IF(AE12<25,""))) | AM12: =IF(AE12=32,AA12*AB12*AC12*AD12*(AE12/1000)*6.313*1,IF(AE12>32,"",IF(AE12<32,""))) | AO12: A | AP12: =SUM(R12:Y12)+SUM(AN12) -> 0 | AQ12: =SUM(AF12:AM12) -> 0 | AS12: ES0101 pormenor tipo de sapatas (5 cm por lado, 10 cm) | AT12: Calculado
B13: ZONA B - BETÃO DE LIMPEZA C16/20 (e=0.10; sobrelargura 0.05 m por lado)
B14: S1 (PB1 a PB5) | C14: 5 | D14: =1.1+2*0.05 -> 1.2 | E14: =1.1+2*0.05 -> 1.2 | F14: 0.1 | G14: =C14*D14*E14*F14 -> 0.72 | I14: =C14*D14*E14 -> 7.2 | R14: =IF(P14=6,N14*O14*Q14*0.222*1,IF(P14>6,"",IF(P14<6,""))) | S14: =IF(P14=8,N14*O14*Q14*0.395*1,IF(P14>8,"",IF(P14<8,""))) | T14: =IF(P14=10,N14*O14*Q14*0.617*1,IF(P14>10,"",IF(P14<10,""))) | U14: =IF(P14=12,N14*O14*Q14*0.888*1,IF(P14>12,"",IF(P14<12,""))) | V14: =IF(P14=16,N14*O14*Q14*1.578*1,IF(P14>16,"",IF(P14<16,""))) | W14: =IF(P14=20,N14*O14*Q14*2.466*1,IF(P14>20,"",IF(P14<20,""))) | X14: =IF(P14=25,N14*O14*Q14*3.853*1,IF(P14>25,"",IF(P14<25,""))) | Y14: =IF(P14=32,N14*O14*Q14*6.313*1,IF(P14>32,"",IF(P14<32,""))) | AA14: =IF(AC14>0,N14,"") | AB14: =IF(AC14>0,O14,"") | AE14: =IF(AC14>0,P14,"") | AF14: =IF(AE14=6,AA14*AB14*AC14*AD14*(AE14/1000)*0.222*1,IF(AE14>6,"",IF(AE14<6,""))) | AG14: =IF(AE14=8,AA14*AB14*AC14*AD14*(AE14/1000)*0.395*1,IF(AE14>8,"",IF(AE14<8,""))) | AH14: =IF(AE14=10,AA14*AB14*AC14*AD14*(AE14/1000)*0.617*1,IF(AE14>10,"",IF(AE14<10,""))) | AI14: =IF(AE14=12,AA14*AB14*AC14*AD14*(AE14/1000)*0.888*1,IF(AE14>12,"",IF(AE14<12,""))) | AJ14: =IF(AE14=16,AA14*AB14*AC14*AD14*(AE14/1000)*1.578*1,IF(AE14>16,"",IF(AE14<16,""))) | AK14: =IF(AE14=20,AA14*AB14*AC14*AD14*(AE14/1000)*2.466*1,IF(AE14>20,"",IF(AE14<20,""))) | AL14: =IF(AE14=25,AA14*AB14*AC14*AD14*(AE14/1000)*3.853*1,IF(AE14>25,"",IF(AE14<25,""))) | AM14: =IF(AE14=32,AA14*AB14*AC14*AD14*(AE14/1000)*6.313*1,IF(AE14>32,"",IF(AE14<32,""))) | AO14: B | AP14: =SUM(R14:Y14)+SUM(AN14) -> 0 | AQ14: =SUM(AF14:AM14) -> 0 | AS14: ES0101 pormenor tipo de sapatas (5 cm por lado, 10 cm) | AT14: Calculado
B15: S5 sob PB6 e PB8 (PB7/PB9 assentam nos poços PF1) | C15: 2 | D15: =1.7+2*0.05 -> 1.8 | E15: =1.2+2*0.05 -> 1.3 | F15: 0.1 | G15: =C15*D15*E15*F15 -> 0.468 | I15: =C15*D15*E15 -> 4.68 | R15: =IF(P15=6,N15*O15*Q15*0.222*1,IF(P15>6,"",IF(P15<6,""))) | S15: =IF(P15=8,N15*O15*Q15*0.395*1,IF(P15>8,"",IF(P15<8,""))) | T15: =IF(P15=10,N15*O15*Q15*0.617*1,IF(P15>10,"",IF(P15<10,""))) | U15: =IF(P15=12,N15*O15*Q15*0.888*1,IF(P15>12,"",IF(P15<12,""))) | V15: =IF(P15=16,N15*O15*Q15*1.578*1,IF(P15>16,"",IF(P15<16,""))) | W15: =IF(P15=20,N15*O15*Q15*2.466*1,IF(P15>20,"",IF(P15<20,""))) | X15: =IF(P15=25,N15*O15*Q15*3.853*1,IF(P15>25,"",IF(P15<25,""))) | Y15: =IF(P15=32,N15*O15*Q15*6.313*1,IF(P15>32,"",IF(P15<32,""))) | AA15: =IF(AC15>0,N15,"") | AB15: =IF(AC15>0,O15,"") | AE15: =IF(AC15>0,P15,"") | AF15: =IF(AE15=6,AA15*AB15*AC15*AD15*(AE15/1000)*0.222*1,IF(AE15>6,"",IF(AE15<6,""))) | AG15: =IF(AE15=8,AA15*AB15*AC15*AD15*(AE15/1000)*0.395*1,IF(AE15>8,"",IF(AE15<8,""))) | AH15: =IF(AE15=10,AA15*AB15*AC15*AD15*(AE15/1000)*0.617*1,IF(AE15>10,"",IF(AE15<10,""))) | AI15: =IF(AE15=12,AA15*AB15*AC15*AD15*(AE15/1000)*0.888*1,IF(AE15>12,"",IF(AE15<12,""))) | AJ15: =IF(AE15=16,AA15*AB15*AC15*AD15*(AE15/1000)*1.578*1,IF(AE15>16,"",IF(AE15<16,""))) | AK15: =IF(AE15=20,AA15*AB15*AC15*AD15*(AE15/1000)*2.466*1,IF(AE15>20,"",IF(AE15<20,""))) | AL15: =IF(AE15=25,AA15*AB15*AC15*AD15*(AE15/1000)*3.853*1,IF(AE15>25,"",IF(AE15<25,""))) | AM15: =IF(AE15=32,AA15*AB15*AC15*AD15*(AE15/1000)*6.313*1,IF(AE15>32,"",IF(AE15<32,""))) | AO15: B | AP15: =SUM(R15:Y15)+SUM(AN15) -> 0 | AQ15: =SUM(AF15:AM15) -> 0 | AS15: ES0201 pormenor de poços: sapata sobre betão ciclópico sem betão de limpeza | AT15: Interpretado
B16: VE1 (b+0.10) x Lcut | C16: 2 | D16: =0.4+2*0.05 -> 0.5 | E16: 4.57 | F16: 0.1 | G16: =C16*D16*E16*F16 -> 0.457 | I16: =C16*D16*E16 -> 4.57 | R16: =IF(P16=6,N16*O16*Q16*0.222*1,IF(P16>6,"",IF(P16<6,""))) | S16: =IF(P16=8,N16*O16*Q16*0.395*1,IF(P16>8,"",IF(P16<8,""))) | T16: =IF(P16=10,N16*O16*Q16*0.617*1,IF(P16>10,"",IF(P16<10,""))) | U16: =IF(P16=12,N16*O16*Q16*0.888*1,IF(P16>12,"",IF(P16<12,""))) | V16: =IF(P16=16,N16*O16*Q16*1.578*1,IF(P16>16,"",IF(P16<16,""))) | W16: =IF(P16=20,N16*O16*Q16*2.466*1,IF(P16>20,"",IF(P16<20,""))) | X16: =IF(P16=25,N16*O16*Q16*3.853*1,IF(P16>25,"",IF(P16<25,""))) | Y16: =IF(P16=32,N16*O16*Q16*6.313*1,IF(P16>32,"",IF(P16<32,""))) | AA16: =IF(AC16>0,N16,"") | AB16: =IF(AC16>0,O16,"") | AE16: =IF(AC16>0,P16,"") | AF16: =IF(AE16=6,AA16*AB16*AC16*AD16*(AE16/1000)*0.222*1,IF(AE16>6,"",IF(AE16<6,""))) | AG16: =IF(AE16=8,AA16*AB16*AC16*AD16*(AE16/1000)*0.395*1,IF(AE16>8,"",IF(AE16<8,""))) | AH16: =IF(AE16=10,AA16*AB16*AC16*AD16*(AE16/1000)*0.617*1,IF(AE16>10,"",IF(AE16<10,""))) | AI16: =IF(AE16=12,AA16*AB16*AC16*AD16*(AE16/1000)*0.888*1,IF(AE16>12,"",IF(AE16<12,""))) | AJ16: =IF(AE16=16,AA16*AB16*AC16*AD16*(AE16/1000)*1.578*1,IF(AE16>16,"",IF(AE16<16,""))) | AK16: =IF(AE16=20,AA16*AB16*AC16*AD16*(AE16/1000)*2.466*1,IF(AE16>20,"",IF(AE16<20,""))) | AL16: =IF(AE16=25,AA16*AB16*AC16*AD16*(AE16/1000)*3.853*1,IF(AE16>25,"",IF(AE16<25,""))) | AM16: =IF(AE16=32,AA16*AB16*AC16*AD16*(AE16/1000)*6.313*1,IF(AE16>32,"",IF(AE16<32,""))) | AO16: B | AP16: =SUM(R16:Y16)+SUM(AN16) -> 0 | AQ16: =SUM(AF16:AM16) -> 0 | AS16: ES0201 det. 4 VE1: "Betão de Limpeza [h=0.10]" | AT16: Calculado
B17: ZONA C - BETÃO DE LIMPEZA C16/20 (e=0.10; sobrelargura 0.05 m por lado)
B18: S2 (PC2, PC4, PC5, PC7) | C18: 4 | D18: =1.7+2*0.05 -> 1.8 | E18: =2.2+2*0.05 -> 2.3 | F18: 0.1 | G18: =C18*D18*E18*F18 -> 1.656 | I18: =C18*D18*E18 -> 16.56 | R18: =IF(P18=6,N18*O18*Q18*0.222*1,IF(P18>6,"",IF(P18<6,""))) | S18: =IF(P18=8,N18*O18*Q18*0.395*1,IF(P18>8,"",IF(P18<8,""))) | T18: =IF(P18=10,N18*O18*Q18*0.617*1,IF(P18>10,"",IF(P18<10,""))) | U18: =IF(P18=12,N18*O18*Q18*0.888*1,IF(P18>12,"",IF(P18<12,""))) | V18: =IF(P18=16,N18*O18*Q18*1.578*1,IF(P18>16,"",IF(P18<16,""))) | W18: =IF(P18=20,N18*O18*Q18*2.466*1,IF(P18>20,"",IF(P18<20,""))) | X18: =IF(P18=25,N18*O18*Q18*3.853*1,IF(P18>25,"",IF(P18<25,""))) | Y18: =IF(P18=32,N18*O18*Q18*6.313*1,IF(P18>32,"",IF(P18<32,""))) | AA18: =IF(AC18>0,N18,"") | AB18: =IF(AC18>0,O18,"") | AE18: =IF(AC18>0,P18,"") | AF18: =IF(AE18=6,AA18*AB18*AC18*AD18*(AE18/1000)*0.222*1,IF(AE18>6,"",IF(AE18<6,""))) | AG18: =IF(AE18=8,AA18*AB18*AC18*AD18*(AE18/1000)*0.395*1,IF(AE18>8,"",IF(AE18<8,""))) | AH18: =IF(AE18=10,AA18*AB18*AC18*AD18*(AE18/1000)*0.617*1,IF(AE18>10,"",IF(AE18<10,""))) | AI18: =IF(AE18=12,AA18*AB18*AC18*AD18*(AE18/1000)*0.888*1,IF(AE18>12,"",IF(AE18<12,""))) | AJ18: =IF(AE18=16,AA18*AB18*AC18*AD18*(AE18/1000)*1.578*1,IF(AE18>16,"",IF(AE18<16,""))) | AK18: =IF(AE18=20,AA18*AB18*AC18*AD18*(AE18/1000)*2.466*1,IF(AE18>20,"",IF(AE18<20,""))) | AL18: =IF(AE18=25,AA18*AB18*AC18*AD18*(AE18/1000)*3.853*1,IF(AE18>25,"",IF(AE18<25,""))) | AM18: =IF(AE18=32,AA18*AB18*AC18*AD18*(AE18/1000)*6.313*1,IF(AE18>32,"",IF(AE18<32,""))) | AO18: C | AP18: =SUM(R18:Y18)+SUM(AN18) -> 0 | AQ18: =SUM(AF18:AM18) -> 0 | AS18: ES0101 pormenor tipo de sapatas (5 cm por lado, 10 cm) | AT18: Calculado
B19: S3 (PC1, PC3, PC6, PC8, PC9, PC10, PC13 + 2 PL1) | C19: 9 | D19: =1.2+2*0.05 -> 1.3 | E19: =1.2+2*0.05 -> 1.3 | F19: 0.1 | G19: =C19*D19*E19*F19 -> 1.521 | I19: =C19*D19*E19 -> 15.21 | R19: =IF(P19=6,N19*O19*Q19*0.222*1,IF(P19>6,"",IF(P19<6,""))) | S19: =IF(P19=8,N19*O19*Q19*0.395*1,IF(P19>8,"",IF(P19<8,""))) | T19: =IF(P19=10,N19*O19*Q19*0.617*1,IF(P19>10,"",IF(P19<10,""))) | U19: =IF(P19=12,N19*O19*Q19*0.888*1,IF(P19>12,"",IF(P19<12,""))) | V19: =IF(P19=16,N19*O19*Q19*1.578*1,IF(P19>16,"",IF(P19<16,""))) | W19: =IF(P19=20,N19*O19*Q19*2.466*1,IF(P19>20,"",IF(P19<20,""))) | X19: =IF(P19=25,N19*O19*Q19*3.853*1,IF(P19>25,"",IF(P19<25,""))) | Y19: =IF(P19=32,N19*O19*Q19*6.313*1,IF(P19>32,"",IF(P19<32,""))) | AA19: =IF(AC19>0,N19,"") | AB19: =IF(AC19>0,O19,"") | AE19: =IF(AC19>0,P19,"") | AF19: =IF(AE19=6,AA19*AB19*AC19*AD19*(AE19/1000)*0.222*1,IF(AE19>6,"",IF(AE19<6,""))) | AG19: =IF(AE19=8,AA19*AB19*AC19*AD19*(AE19/1000)*0.395*1,IF(AE19>8,"",IF(AE19<8,""))) | AH19: =IF(AE19=10,AA19*AB19*AC19*AD19*(AE19/1000)*0.617*1,IF(AE19>10,"",IF(AE19<10,""))) | AI19: =IF(AE19=12,AA19*AB19*AC19*AD19*(AE19/1000)*0.888*1,IF(AE19>12,"",IF(AE19<12,""))) | AJ19: =IF(AE19=16,AA19*AB19*AC19*AD19*(AE19/1000)*1.578*1,IF(AE19>16,"",IF(AE19<16,""))) | AK19: =IF(AE19=20,AA19*AB19*AC19*AD19*(AE19/1000)*2.466*1,IF(AE19>20,"",IF(AE19<20,""))) | AL19: =IF(AE19=25,AA19*AB19*AC19*AD19*(AE19/1000)*3.853*1,IF(AE19>25,"",IF(AE19<25,""))) | AM19: =IF(AE19=32,AA19*AB19*AC19*AD19*(AE19/1000)*6.313*1,IF(AE19>32,"",IF(AE19<32,""))) | AO19: C | AP19: =SUM(R19:Y19)+SUM(AN19) -> 0 | AQ19: =SUM(AF19:AM19) -> 0 | AS19: ES0101 pormenor tipo de sapatas (5 cm por lado, 10 cm) | AT19: Calculado
B20: S4 (PL1 em CE) | C20: 2 | D20: =1.4+2*0.05 -> 1.5 | E20: =0.8+2*0.05 -> 0.9 | F20: 0.1 | G20: =C20*D20*E20*F20 -> 0.27 | I20: =C20*D20*E20 -> 2.7 | R20: =IF(P20=6,N20*O20*Q20*0.222*1,IF(P20>6,"",IF(P20<6,""))) | S20: =IF(P20=8,N20*O20*Q20*0.395*1,IF(P20>8,"",IF(P20<8,""))) | T20: =IF(P20=10,N20*O20*Q20*0.617*1,IF(P20>10,"",IF(P20<10,""))) | U20: =IF(P20=12,N20*O20*Q20*0.888*1,IF(P20>12,"",IF(P20<12,""))) | V20: =IF(P20=16,N20*O20*Q20*1.578*1,IF(P20>16,"",IF(P20<16,""))) | W20: =IF(P20=20,N20*O20*Q20*2.466*1,IF(P20>20,"",IF(P20<20,""))) | X20: =IF(P20=25,N20*O20*Q20*3.853*1,IF(P20>25,"",IF(P20<25,""))) | Y20: =IF(P20=32,N20*O20*Q20*6.313*1,IF(P20>32,"",IF(P20<32,""))) | AA20: =IF(AC20>0,N20,"") | AB20: =IF(AC20>0,O20,"") | AE20: =IF(AC20>0,P20,"") | AF20: =IF(AE20=6,AA20*AB20*AC20*AD20*(AE20/1000)*0.222*1,IF(AE20>6,"",IF(AE20<6,""))) | AG20: =IF(AE20=8,AA20*AB20*AC20*AD20*(AE20/1000)*0.395*1,IF(AE20>8,"",IF(AE20<8,""))) | AH20: =IF(AE20=10,AA20*AB20*AC20*AD20*(AE20/1000)*0.617*1,IF(AE20>10,"",IF(AE20<10,""))) | AI20: =IF(AE20=12,AA20*AB20*AC20*AD20*(AE20/1000)*0.888*1,IF(AE20>12,"",IF(AE20<12,""))) | AJ20: =IF(AE20=16,AA20*AB20*AC20*AD20*(AE20/1000)*1.578*1,IF(AE20>16,"",IF(AE20<16,""))) | AK20: =IF(AE20=20,AA20*AB20*AC20*AD20*(AE20/1000)*2.466*1,IF(AE20>20,"",IF(AE20<20,""))) | AL20: =IF(AE20=25,AA20*AB20*AC20*AD20*(AE20/1000)*3.853*1,IF(AE20>25,"",IF(AE20<25,""))) | AM20: =IF(AE20=32,AA20*AB20*AC20*AD20*(AE20/1000)*6.313*1,IF(AE20>32,"",IF(AE20<32,""))) | AO20: C | AP20: =SUM(R20:Y20)+SUM(AN20) -> 0 | AQ20: =SUM(AF20:AM20) -> 0 | AS20: ES0101 pormenor tipo de sapatas (5 cm por lado, 10 cm) | AT20: Calculado
B21: VL1 (b+0.10) x ΣLcut (11 tramos) | C21: 1 | D21: =0.24+2*0.05 -> 0.34 | E21: =7.0887+5.3877+7.5463+1.3315+3.3468+4.2949+2.5778+3.4271+1.7234+7.5463+3.3342 -> 47.6047 | F21: 0.1 | G21: =C21*D21*E21*F21 -> 1.6185598 | I21: =C21*D21*E21 -> 16.185598 | R21: =IF(P21=6,N21*O21*Q21*0.222*1,IF(P21>6,"",IF(P21<6,""))) | S21: =IF(P21=8,N21*O21*Q21*0.395*1,IF(P21>8,"",IF(P21<8,""))) | T21: =IF(P21=10,N21*O21*Q21*0.617*1,IF(P21>10,"",IF(P21<10,""))) | U21: =IF(P21=12,N21*O21*Q21*0.888*1,IF(P21>12,"",IF(P21<12,""))) | V21: =IF(P21=16,N21*O21*Q21*1.578*1,IF(P21>16,"",IF(P21<16,""))) | W21: =IF(P21=20,N21*O21*Q21*2.466*1,IF(P21>20,"",IF(P21<20,""))) | X21: =IF(P21=25,N21*O21*Q21*3.853*1,IF(P21>25,"",IF(P21<25,""))) | Y21: =IF(P21=32,N21*O21*Q21*6.313*1,IF(P21>32,"",IF(P21<32,""))) | AA21: =IF(AC21>0,N21,"") | AB21: =IF(AC21>0,O21,"") | AE21: =IF(AC21>0,P21,"") | AF21: =IF(AE21=6,AA21*AB21*AC21*AD21*(AE21/1000)*0.222*1,IF(AE21>6,"",IF(AE21<6,""))) | AG21: =IF(AE21=8,AA21*AB21*AC21*AD21*(AE21/1000)*0.395*1,IF(AE21>8,"",IF(AE21<8,""))) | AH21: =IF(AE21=10,AA21*AB21*AC21*AD21*(AE21/1000)*0.617*1,IF(AE21>10,"",IF(AE21<10,""))) | AI21: =IF(AE21=12,AA21*AB21*AC21*AD21*(AE21/1000)*0.888*1,IF(AE21>12,"",IF(AE21<12,""))) | AJ21: =IF(AE21=16,AA21*AB21*AC21*AD21*(AE21/1000)*1.578*1,IF(AE21>16,"",IF(AE21<16,""))) | AK21: =IF(AE21=20,AA21*AB21*AC21*AD21*(AE21/1000)*2.466*1,IF(AE21>20,"",IF(AE21<20,""))) | AL21: =IF(AE21=25,AA21*AB21*AC21*AD21*(AE21/1000)*3.853*1,IF(AE21>25,"",IF(AE21<25,""))) | AM21: =IF(AE21=32,AA21*AB21*AC21*AD21*(AE21/1000)*6.313*1,IF(AE21>32,"",IF(AE21<32,""))) | AO21: C | AP21: =SUM(R21:Y21)+SUM(AN21) -> 0 | AQ21: =SUM(AF21:AM21) -> 0 | AS21: ES0302 det. 3 VL1: "Betão Limpeza" | AT21: Calculado
B22: ZONA D - BETÃO DE LIMPEZA C16/20 (e=0.10; sobrelargura 0.05 m por lado)
B23: SE1 (PE1) | C23: 1 | D23: =1.1+2*0.05 -> 1.2 | E23: =1.1+2*0.05 -> 1.2 | F23: 0.1 | G23: =C23*D23*E23*F23 -> 0.144 | I23: =C23*D23*E23 -> 1.44 | R23: =IF(P23=6,N23*O23*Q23*0.222*1,IF(P23>6,"",IF(P23<6,""))) | S23: =IF(P23=8,N23*O23*Q23*0.395*1,IF(P23>8,"",IF(P23<8,""))) | T23: =IF(P23=10,N23*O23*Q23*0.617*1,IF(P23>10,"",IF(P23<10,""))) | U23: =IF(P23=12,N23*O23*Q23*0.888*1,IF(P23>12,"",IF(P23<12,""))) | V23: =IF(P23=16,N23*O23*Q23*1.578*1,IF(P23>16,"",IF(P23<16,""))) | W23: =IF(P23=20,N23*O23*Q23*2.466*1,IF(P23>20,"",IF(P23<20,""))) | X23: =IF(P23=25,N23*O23*Q23*3.853*1,IF(P23>25,"",IF(P23<25,""))) | Y23: =IF(P23=32,N23*O23*Q23*6.313*1,IF(P23>32,"",IF(P23<32,""))) | AA23: =IF(AC23>0,N23,"") | AB23: =IF(AC23>0,O23,"") | AE23: =IF(AC23>0,P23,"") | AF23: =IF(AE23=6,AA23*AB23*AC23*AD23*(AE23/1000)*0.222*1,IF(AE23>6,"",IF(AE23<6,""))) | AG23: =IF(AE23=8,AA23*AB23*AC23*AD23*(AE23/1000)*0.395*1,IF(AE23>8,"",IF(AE23<8,""))) | AH23: =IF(AE23=10,AA23*AB23*AC23*AD23*(AE23/1000)*0.617*1,IF(AE23>10,"",IF(AE23<10,""))) | AI23: =IF(AE23=12,AA23*AB23*AC23*AD23*(AE23/1000)*0.888*1,IF(AE23>12,"",IF(AE23<12,""))) | AJ23: =IF(AE23=16,AA23*AB23*AC23*AD23*(AE23/1000)*1.578*1,IF(AE23>16,"",IF(AE23<16,""))) | AK23: =IF(AE23=20,AA23*AB23*AC23*AD23*(AE23/1000)*2.466*1,IF(AE23>20,"",IF(AE23<20,""))) | AL23: =IF(AE23=25,AA23*AB23*AC23*AD23*(AE23/1000)*3.853*1,IF(AE23>25,"",IF(AE23<25,""))) | AM23: =IF(AE23=32,AA23*AB23*AC23*AD23*(AE23/1000)*6.313*1,IF(AE23>32,"",IF(AE23<32,""))) | AO23: D | AP23: =SUM(R23:Y23)+SUM(AN23) -> 0 | AQ23: =SUM(AF23:AM23) -> 0 | AS23: ES0101 pormenor tipo de sapatas (5 cm por lado, 10 cm) | AT23: Calculado
B24: ZONA F - BETÃO DE LIMPEZA C16/20 (e=0.10; sobrelargura 0.05 m por lado)
B25: LMFelev - ensoleiramento do elevador | C25: 1 | D25: =3.15+2*0.05 -> 3.25 | E25: =2.74+2*0.05 -> 2.84 | F25: 0.1 | G25: =C25*D25*E25*F25 -> 0.923 | I25: =C25*D25*E25 -> 9.23 | R25: =IF(P25=6,N25*O25*Q25*0.222*1,IF(P25>6,"",IF(P25<6,""))) | S25: =IF(P25=8,N25*O25*Q25*0.395*1,IF(P25>8,"",IF(P25<8,""))) | T25: =IF(P25=10,N25*O25*Q25*0.617*1,IF(P25>10,"",IF(P25<10,""))) | U25: =IF(P25=12,N25*O25*Q25*0.888*1,IF(P25>12,"",IF(P25<12,""))) | V25: =IF(P25=16,N25*O25*Q25*1.578*1,IF(P25>16,"",IF(P25<16,""))) | W25: =IF(P25=20,N25*O25*Q25*2.466*1,IF(P25>20,"",IF(P25<20,""))) | X25: =IF(P25=25,N25*O25*Q25*3.853*1,IF(P25>25,"",IF(P25<25,""))) | Y25: =IF(P25=32,N25*O25*Q25*6.313*1,IF(P25>32,"",IF(P25<32,""))) | AA25: =IF(AC25>0,N25,"") | AB25: =IF(AC25>0,O25,"") | AE25: =IF(AC25>0,P25,"") | AF25: =IF(AE25=6,AA25*AB25*AC25*AD25*(AE25/1000)*0.222*1,IF(AE25>6,"",IF(AE25<6,""))) | AG25: =IF(AE25=8,AA25*AB25*AC25*AD25*(AE25/1000)*0.395*1,IF(AE25>8,"",IF(AE25<8,""))) | AH25: =IF(AE25=10,AA25*AB25*AC25*AD25*(AE25/1000)*0.617*1,IF(AE25>10,"",IF(AE25<10,""))) | AI25: =IF(AE25=12,AA25*AB25*AC25*AD25*(AE25/1000)*0.888*1,IF(AE25>12,"",IF(AE25<12,""))) | AJ25: =IF(AE25=16,AA25*AB25*AC25*AD25*(AE25/1000)*1.578*1,IF(AE25>16,"",IF(AE25<16,""))) | AK25: =IF(AE25=20,AA25*AB25*AC25*AD25*(AE25/1000)*2.466*1,IF(AE25>20,"",IF(AE25<20,""))) | AL25: =IF(AE25=25,AA25*AB25*AC25*AD25*(AE25/1000)*3.853*1,IF(AE25>25,"",IF(AE25<25,""))) | AM25: =IF(AE25=32,AA25*AB25*AC25*AD25*(AE25/1000)*6.313*1,IF(AE25>32,"",IF(AE25<32,""))) | AO25: F | AP25: =SUM(R25:Y25)+SUM(AN25) -> 0 | AQ25: =SUM(AF25:AM25) -> 0 | AS25: ES0101 pormenor tipo de sapatas (5 cm por lado, 10 cm) | AT25: Calculado
B26: ZONA E - BETÃO DE LIMPEZA SOB SAPATAS CONTÍNUAS DO MURO
B27: SMS1.1 (sob MS1.1) | C27: 1 | D27: =1.6965/(1.45*0.5)+2*0.05 -> 2.44 | E27: =1.45+2*0.05 -> 1.55 | F27: 0.1 | G27: =C27*D27*E27*F27 -> 0.3782 | I27: =C27*D27*E27 -> 3.782 | R27: =IF(P27=6,N27*O27*Q27*0.222*1,IF(P27>6,"",IF(P27<6,""))) | S27: =IF(P27=8,N27*O27*Q27*0.395*1,IF(P27>8,"",IF(P27<8,""))) | T27: =IF(P27=10,N27*O27*Q27*0.617*1,IF(P27>10,"",IF(P27<10,""))) | U27: =IF(P27=12,N27*O27*Q27*0.888*1,IF(P27>12,"",IF(P27<12,""))) | V27: =IF(P27=16,N27*O27*Q27*1.578*1,IF(P27>16,"",IF(P27<16,""))) | W27: =IF(P27=20,N27*O27*Q27*2.466*1,IF(P27>20,"",IF(P27<20,""))) | X27: =IF(P27=25,N27*O27*Q27*3.853*1,IF(P27>25,"",IF(P27<25,""))) | Y27: =IF(P27=32,N27*O27*Q27*6.313*1,IF(P27>32,"",IF(P27<32,""))) | AA27: =IF(AC27>0,N27,"") | AB27: =IF(AC27>0,O27,"") | AE27: =IF(AC27>0,P27,"") | AF27: =IF(AE27=6,AA27*AB27*AC27*AD27*(AE27/1000)*0.222*1,IF(AE27>6,"",IF(AE27<6,""))) | AG27: =IF(AE27=8,AA27*AB27*AC27*AD27*(AE27/1000)*0.395*1,IF(AE27>8,"",IF(AE27<8,""))) | AH27: =IF(AE27=10,AA27*AB27*AC27*AD27*(AE27/1000)*0.617*1,IF(AE27>10,"",IF(AE27<10,""))) | AI27: =IF(AE27=12,AA27*AB27*AC27*AD27*(AE27/1000)*0.888*1,IF(AE27>12,"",IF(AE27<12,""))) | AJ27: =IF(AE27=16,AA27*AB27*AC27*AD27*(AE27/1000)*1.578*1,IF(AE27>16,"",IF(AE27<16,""))) | AK27: =IF(AE27=20,AA27*AB27*AC27*AD27*(AE27/1000)*2.466*1,IF(AE27>20,"",IF(AE27<20,""))) | AL27: =IF(AE27=25,AA27*AB27*AC27*AD27*(AE27/1000)*3.853*1,IF(AE27>25,"",IF(AE27<25,""))) | AM27: =IF(AE27=32,AA27*AB27*AC27*AD27*(AE27/1000)*6.313*1,IF(AE27>32,"",IF(AE27<32,""))) | AO27: E | AP27: =SUM(R27:Y27)+SUM(AN27) -> 0 | AQ27: =SUM(AF27:AM27) -> 0 | AS27: ES0401 det. 3-5 (limpeza 0.10) | AT27: Calculado
B28: SMS1.2 (sob MS1.2) | C28: 1 | D28: =2.8275/(1.45*0.5)+2*0.05 -> 4 | E28: =1.45+2*0.05 -> 1.55 | F28: 0.1 | G28: =C28*D28*E28*F28 -> 0.62 | I28: =C28*D28*E28 -> 6.2 | R28: =IF(P28=6,N28*O28*Q28*0.222*1,IF(P28>6,"",IF(P28<6,""))) | S28: =IF(P28=8,N28*O28*Q28*0.395*1,IF(P28>8,"",IF(P28<8,""))) | T28: =IF(P28=10,N28*O28*Q28*0.617*1,IF(P28>10,"",IF(P28<10,""))) | U28: =IF(P28=12,N28*O28*Q28*0.888*1,IF(P28>12,"",IF(P28<12,""))) | V28: =IF(P28=16,N28*O28*Q28*1.578*1,IF(P28>16,"",IF(P28<16,""))) | W28: =IF(P28=20,N28*O28*Q28*2.466*1,IF(P28>20,"",IF(P28<20,""))) | X28: =IF(P28=25,N28*O28*Q28*3.853*1,IF(P28>25,"",IF(P28<25,""))) | Y28: =IF(P28=32,N28*O28*Q28*6.313*1,IF(P28>32,"",IF(P28<32,""))) | AA28: =IF(AC28>0,N28,"") | AB28: =IF(AC28>0,O28,"") | AE28: =IF(AC28>0,P28,"") | AF28: =IF(AE28=6,AA28*AB28*AC28*AD28*(AE28/1000)*0.222*1,IF(AE28>6,"",IF(AE28<6,""))) | AG28: =IF(AE28=8,AA28*AB28*AC28*AD28*(AE28/1000)*0.395*1,IF(AE28>8,"",IF(AE28<8,""))) | AH28: =IF(AE28=10,AA28*AB28*AC28*AD28*(AE28/1000)*0.617*1,IF(AE28>10,"",IF(AE28<10,""))) | AI28: =IF(AE28=12,AA28*AB28*AC28*AD28*(AE28/1000)*0.888*1,IF(AE28>12,"",IF(AE28<12,""))) | AJ28: =IF(AE28=16,AA28*AB28*AC28*AD28*(AE28/1000)*1.578*1,IF(AE28>16,"",IF(AE28<16,""))) | AK28: =IF(AE28=20,AA28*AB28*AC28*AD28*(AE28/1000)*2.466*1,IF(AE28>20,"",IF(AE28<20,""))) | AL28: =IF(AE28=25,AA28*AB28*AC28*AD28*(AE28/1000)*3.853*1,IF(AE28>25,"",IF(AE28<25,""))) | AM28: =IF(AE28=32,AA28*AB28*AC28*AD28*(AE28/1000)*6.313*1,IF(AE28>32,"",IF(AE28<32,""))) | AO28: E | AP28: =SUM(R28:Y28)+SUM(AN28) -> 0 | AQ28: =SUM(AF28:AM28) -> 0 | AS28: ES0401 det. 3-5 (limpeza 0.10) | AT28: Calculado
B29: SMS1.3 (sob MS1.3) | C29: 1 | D29: =2.415/(1.15*0.5)+2*0.05 -> 4.3 | E29: =1.15+2*0.05 -> 1.25 | F29: 0.1 | G29: =C29*D29*E29*F29 -> 0.5375 | I29: =C29*D29*E29 -> 5.375 | R29: =IF(P29=6,N29*O29*Q29*0.222*1,IF(P29>6,"",IF(P29<6,""))) | S29: =IF(P29=8,N29*O29*Q29*0.395*1,IF(P29>8,"",IF(P29<8,""))) | T29: =IF(P29=10,N29*O29*Q29*0.617*1,IF(P29>10,"",IF(P29<10,""))) | U29: =IF(P29=12,N29*O29*Q29*0.888*1,IF(P29>12,"",IF(P29<12,""))) | V29: =IF(P29=16,N29*O29*Q29*1.578*1,IF(P29>16,"",IF(P29<16,""))) | W29: =IF(P29=20,N29*O29*Q29*2.466*1,IF(P29>20,"",IF(P29<20,""))) | X29: =IF(P29=25,N29*O29*Q29*3.853*1,IF(P29>25,"",IF(P29<25,""))) | Y29: =IF(P29=32,N29*O29*Q29*6.313*1,IF(P29>32,"",IF(P29<32,""))) | AA29: =IF(AC29>0,N29,"") | AB29: =IF(AC29>0,O29,"") | AE29: =IF(AC29>0,P29,"") | AF29: =IF(AE29=6,AA29*AB29*AC29*AD29*(AE29/1000)*0.222*1,IF(AE29>6,"",IF(AE29<6,""))) | AG29: =IF(AE29=8,AA29*AB29*AC29*AD29*(AE29/1000)*0.395*1,IF(AE29>8,"",IF(AE29<8,""))) | AH29: =IF(AE29=10,AA29*AB29*AC29*AD29*(AE29/1000)*0.617*1,IF(AE29>10,"",IF(AE29<10,""))) | AI29: =IF(AE29=12,AA29*AB29*AC29*AD29*(AE29/1000)*0.888*1,IF(AE29>12,"",IF(AE29<12,""))) | AJ29: =IF(AE29=16,AA29*AB29*AC29*AD29*(AE29/1000)*1.578*1,IF(AE29>16,"",IF(AE29<16,""))) | AK29: =IF(AE29=20,AA29*AB29*AC29*AD29*(AE29/1000)*2.466*1,IF(AE29>20,"",IF(AE29<20,""))) | AL29: =IF(AE29=25,AA29*AB29*AC29*AD29*(AE29/1000)*3.853*1,IF(AE29>25,"",IF(AE29<25,""))) | AM29: =IF(AE29=32,AA29*AB29*AC29*AD29*(AE29/1000)*6.313*1,IF(AE29>32,"",IF(AE29<32,""))) | AO29: E | AP29: =SUM(R29:Y29)+SUM(AN29) -> 0 | AQ29: =SUM(AF29:AM29) -> 0 | AS29: ES0401 det. 3-5 (limpeza 0.10) | AT29: Calculado
B30: SMS1.4 (sob MS1.4) | C30: 1 | D30: =1.4365/(0.85*0.4)+2*0.05 -> 4.325 | E30: =0.85+2*0.05 -> 0.95 | F30: 0.1 | G30: =C30*D30*E30*F30 -> 0.410875 | I30: =C30*D30*E30 -> 4.10875 | R30: =IF(P30=6,N30*O30*Q30*0.222*1,IF(P30>6,"",IF(P30<6,""))) | S30: =IF(P30=8,N30*O30*Q30*0.395*1,IF(P30>8,"",IF(P30<8,""))) | T30: =IF(P30=10,N30*O30*Q30*0.617*1,IF(P30>10,"",IF(P30<10,""))) | U30: =IF(P30=12,N30*O30*Q30*0.888*1,IF(P30>12,"",IF(P30<12,""))) | V30: =IF(P30=16,N30*O30*Q30*1.578*1,IF(P30>16,"",IF(P30<16,""))) | W30: =IF(P30=20,N30*O30*Q30*2.466*1,IF(P30>20,"",IF(P30<20,""))) | X30: =IF(P30=25,N30*O30*Q30*3.853*1,IF(P30>25,"",IF(P30<25,""))) | Y30: =IF(P30=32,N30*O30*Q30*6.313*1,IF(P30>32,"",IF(P30<32,""))) | AA30: =IF(AC30>0,N30,"") | AB30: =IF(AC30>0,O30,"") | AE30: =IF(AC30>0,P30,"") | AF30: =IF(AE30=6,AA30*AB30*AC30*AD30*(AE30/1000)*0.222*1,IF(AE30>6,"",IF(AE30<6,""))) | AG30: =IF(AE30=8,AA30*AB30*AC30*AD30*(AE30/1000)*0.395*1,IF(AE30>8,"",IF(AE30<8,""))) | AH30: =IF(AE30=10,AA30*AB30*AC30*AD30*(AE30/1000)*0.617*1,IF(AE30>10,"",IF(AE30<10,""))) | AI30: =IF(AE30=12,AA30*AB30*AC30*AD30*(AE30/1000)*0.888*1,IF(AE30>12,"",IF(AE30<12,""))) | AJ30: =IF(AE30=16,AA30*AB30*AC30*AD30*(AE30/1000)*1.578*1,IF(AE30>16,"",IF(AE30<16,""))) | AK30: =IF(AE30=20,AA30*AB30*AC30*AD30*(AE30/1000)*2.466*1,IF(AE30>20,"",IF(AE30<20,""))) | AL30: =IF(AE30=25,AA30*AB30*AC30*AD30*(AE30/1000)*3.853*1,IF(AE30>25,"",IF(AE30<25,""))) | AM30: =IF(AE30=32,AA30*AB30*AC30*AD30*(AE30/1000)*6.313*1,IF(AE30>32,"",IF(AE30<32,""))) | AO30: E | AP30: =SUM(R30:Y30)+SUM(AN30) -> 0 | AQ30: =SUM(AF30:AM30) -> 0 | AS30: ES0401 det. 3-5 (limpeza 0.10) | AT30: Calculado
C32: TOTAL BETÃO (m3) | G32: =SUM(G6:G30) -> 11.950635 | O32: TOTAL (kg/Ø) | R32: =SUM(R6:R30) -> 0 | S32: =SUM(S6:S30) -> 0 | T32: =SUM(T6:T30) -> 0 | U32: =SUM(U6:U30) -> 0 | V32: =SUM(V6:V30) -> 0 | W32: =SUM(W6:W30) -> 0 | X32: =SUM(X6:X30) -> 0 | Y32: =SUM(Y6:Y30) -> 0 | AB32: TOTAL (kg/Ø) | AF32: =SUM(AF6:AF30) -> 0 | AG32: =SUM(AG6:AG30) -> 0 | AH32: =SUM(AH6:AH30) -> 0 | AI32: =SUM(AI6:AI30) -> 0 | AJ32: =SUM(AJ6:AJ30) -> 0 | AK32: =SUM(AK6:AK30) -> 0 | AL32: =SUM(AL6:AL30) -> 0 | AM32: =SUM(AM6:AM30) -> 0 | AN32: =SUM(AN6:AN30) -> 0
A33: OBS : | C33: TOTAL COFRAGEM (m2) | G33: =SUM(I6:I30) -> 119.50635 | O33: TOTAL (Kg) | R33: =SUM(R32:Y32)+AN32 -> 0 | AB33: TOTAL (Kg) | AF33: =SUM(AF32:AM32) -> 0
C34: DENS. COFRAGEM (m2/m3) | G34: =IF(G32>0,G33/G32,0) -> 10 | O34: DENS. TOTAL (Kg/m3) | R34: =IF(G32>0,R33/G32,0) -> 0 | AB34: DENS. EMPALMES (Kg/m3) | AF34: =IF(G32>0,AF33/G32,0) -> 0 | AJ34: % EMPALMES/kg | AM34: =IF(R33>0,AF33/R33,0) -> 0

Sheet FUNDAÇÕES
E1: MEDIÇÕES DE BETÃO ARMADO | S1: Obra: | T1: 050.24 - LAR DE S. JORGE, GMR | W1: Executou:
S2: Local: | T2: Pevidém, Guimarães | W2: Data: | X2: =TODAY() -> 46325
A4: ARTº | B4: Designação | C4: BETÃO | I4: COFRAGEM | K4: AÇO SEM EMPALMES | R4: DIÃMETROS | AA4: AÇO EMPALMES | AF4: DIÃMETROS | AN4: REDE ELECTROS. | AO4: ZONA | AP4: AÇO s/ EMP. (kg) | AQ4: AÇO EMP. (kg) | AR4: BETÃO MODELO BIM (m3) | AS4: FONTE / OBSERVAÇÕES | AT4: ESTADO
C5: Nº | D5: C (BX) | E5: L (BY) | F5: H | G5: PARCIAL | I5: PARCIAL | K5: Designação | L5: L | M5: P | N5: Nº (PI) | O5: QUANT. | P5: Ø | Q5: COMP. | R5: Ø 6 | S5: Ø 8 | T5: Ø 10 | U5: Ø 12 | V5: Ø 16 | W5: Ø 20 | X5: Ø 25 | Y5: Ø 32 | AA5: Nº (PI) | AB5: nº varões | AC5: nº empalmes | AD5: ɸ | AE5: Ø | AF5: Ø 6 | AG5: Ø 8 | AH5: Ø 10 | AI5: Ø 12 | AJ5: Ø 16 | AK5: Ø 20 | AL5: Ø 25 | AM5: Ø 32 | AN5: (kg)
B6: ZONA A - SAPATAS ISOLADAS
B7: S6 (PA1, PA2) | C7: 1 | D7: 2.4 | E7: 2.8 | F7: 0.5 | G7: =C7*D7*E7*F7 -> 3.36 | I7: =2*(D7+E7)*F7*C7 -> 5.2 | R7: =IF(P7=6,N7*O7*Q7*0.222*1,IF(P7>6,"",IF(P7<6,""))) | S7: =IF(P7=8,N7*O7*Q7*0.395*1,IF(P7>8,"",IF(P7<8,""))) | T7: =IF(P7=10,N7*O7*Q7*0.617*1,IF(P7>10,"",IF(P7<10,""))) | U7: =IF(P7=12,N7*O7*Q7*0.888*1,IF(P7>12,"",IF(P7<12,""))) | V7: =IF(P7=16,N7*O7*Q7*1.578*1,IF(P7>16,"",IF(P7<16,""))) | W7: =IF(P7=20,N7*O7*Q7*2.466*1,IF(P7>20,"",IF(P7<20,""))) | X7: =IF(P7=25,N7*O7*Q7*3.853*1,IF(P7>25,"",IF(P7<25,""))) | Y7: =IF(P7=32,N7*O7*Q7*6.313*1,IF(P7>32,"",IF(P7<32,""))) | AA7: =IF(AC7>0,N7,"") | AB7: =IF(AC7>0,O7,"") | AE7: =IF(AC7>0,P7,"") | AF7: =IF(AE7=6,AA7*AB7*AC7*AD7*(AE7/1000)*0.222*1,IF(AE7>6,"",IF(AE7<6,""))) | AG7: =IF(AE7=8,AA7*AB7*AC7*AD7*(AE7/1000)*0.395*1,IF(AE7>8,"",IF(AE7<8,""))) | AH7: =IF(AE7=10,AA7*AB7*AC7*AD7*(AE7/1000)*0.617*1,IF(AE7>10,"",IF(AE7<10,""))) | AI7: =IF(AE7=12,AA7*AB7*AC7*AD7*(AE7/1000)*0.888*1,IF(AE7>12,"",IF(AE7<12,""))) | AJ7: =IF(AE7=16,AA7*AB7*AC7*AD7*(AE7/1000)*1.578*1,IF(AE7>16,"",IF(AE7<16,""))) | AK7: =IF(AE7=20,AA7*AB7*AC7*AD7*(AE7/1000)*2.466*1,IF(AE7>20,"",IF(AE7<20,""))) | AL7: =IF(AE7=25,AA7*AB7*AC7*AD7*(AE7/1000)*3.853*1,IF(AE7>25,"",IF(AE7<25,""))) | AM7: =IF(AE7=32,AA7*AB7*AC7*AD7*(AE7/1000)*6.313*1,IF(AE7>32,"",IF(AE7<32,""))) | AO7: A | AP7: =SUM(R7:Y7)+SUM(AN7) -> 0 | AQ7: =SUM(AF7:AM7) -> 0 | AR7: 3.36 | AS7: ES0101 quadro sapatas Zona A; Revit 1374132 | AT7: Extraído
K8: AS inf xx Ø16//0.125 | L8: =$E$7-2*0.05 -> 2.7 | M8: 0.125 | N8: =$C$7 -> 1 | O8: =CEILING(L8/M8,1)+1 -> 23 | P8: 16 | Q8: =$D$7-2*0.05+2*($F$7-2*0.05) -> 3.1 | R8: =IF(P8=6,N8*O8*Q8*0.222*1,IF(P8>6,"",IF(P8<6,""))) | S8: =IF(P8=8,N8*O8*Q8*0.395*1,IF(P8>8,"",IF(P8<8,""))) | T8: =IF(P8=10,N8*O8*Q8*0.617*1,IF(P8>10,"",IF(P8<10,""))) | U8: =IF(P8=12,N8*O8*Q8*0.888*1,IF(P8>12,"",IF(P8<12,""))) | V8: =IF(P8=16,N8*O8*Q8*1.578*1,IF(P8>16,"",IF(P8<16,""))) -> 112.5114 | W8: =IF(P8=20,N8*O8*Q8*2.466*1,IF(P8>20,"",IF(P8<20,""))) | X8: =IF(P8=25,N8*O8*Q8*3.853*1,IF(P8>25,"",IF(P8<25,""))) | Y8: =IF(P8=32,N8*O8*Q8*6.313*1,IF(P8>32,"",IF(P8<32,""))) | AA8: =IF(AC8>0,N8,"") | AB8: =IF(AC8>0,O8,"") | AE8: =IF(AC8>0,P8,"") | AF8: =IF(AE8=6,AA8*AB8*AC8*AD8*(AE8/1000)*0.222*1,IF(AE8>6,"",IF(AE8<6,""))) | AG8: =IF(AE8=8,AA8*AB8*AC8*AD8*(AE8/1000)*0.395*1,IF(AE8>8,"",IF(AE8<8,""))) | AH8: =IF(AE8=10,AA8*AB8*AC8*AD8*(AE8/1000)*0.617*1,IF(AE8>10,"",IF(AE8<10,""))) | AI8: =IF(AE8=12,AA8*AB8*AC8*AD8*(AE8/1000)*0.888*1,IF(AE8>12,"",IF(AE8<12,""))) | AJ8: =IF(AE8=16,AA8*AB8*AC8*AD8*(AE8/1000)*1.578*1,IF(AE8>16,"",IF(AE8<16,""))) | AK8: =IF(AE8=20,AA8*AB8*AC8*AD8*(AE8/1000)*2.466*1,IF(AE8>20,"",IF(AE8<20,""))) | AL8: =IF(AE8=25,AA8*AB8*AC8*AD8*(AE8/1000)*3.853*1,IF(AE8>25,"",IF(AE8<25,""))) | AM8: =IF(AE8=32,AA8*AB8*AC8*AD8*(AE8/1000)*6.313*1,IF(AE8>32,"",IF(AE8<32,""))) | AO8: A | AP8: =SUM(R8:Y8)+SUM(AN8) -> 112.5114 | AQ8: =SUM(AF8:AM8) -> 0 | AS8: varão em U (abas até à face oposta); recobrimento 5 cm (ES0101 pormenor tipo de sapatas) | AT8: Calculado
K9: AS inf yy Ø16//0.125 | L9: =$D$7-2*0.05 -> 2.3 | M9: 0.125 | N9: =$C$7 -> 1 | O9: =CEILING(L9/M9,1)+1 -> 20 | P9: 16 | Q9: =$E$7-2*0.05+2*($F$7-2*0.05) -> 3.5 | R9: =IF(P9=6,N9*O9*Q9*0.222*1,IF(P9>6,"",IF(P9<6,""))) | S9: =IF(P9=8,N9*O9*Q9*0.395*1,IF(P9>8,"",IF(P9<8,""))) | T9: =IF(P9=10,N9*O9*Q9*0.617*1,IF(P9>10,"",IF(P9<10,""))) | U9: =IF(P9=12,N9*O9*Q9*0.888*1,IF(P9>12,"",IF(P9<12,""))) | V9: =IF(P9=16,N9*O9*Q9*1.578*1,IF(P9>16,"",IF(P9<16,""))) -> 110.46 | W9: =IF(P9=20,N9*O9*Q9*2.466*1,IF(P9>20,"",IF(P9<20,""))) | X9: =IF(P9=25,N9*O9*Q9*3.853*1,IF(P9>25,"",IF(P9<25,""))) | Y9: =IF(P9=32,N9*O9*Q9*6.313*1,IF(P9>32,"",IF(P9<32,""))) | AA9: =IF(AC9>0,N9,"") | AB9: =IF(AC9>0,O9,"") | AE9: =IF(AC9>0,P9,"") | AF9: =IF(AE9=6,AA9*AB9*AC9*AD9*(AE9/1000)*0.222*1,IF(AE9>6,"",IF(AE9<6,""))) | AG9: =IF(AE9=8,AA9*AB9*AC9*AD9*(AE9/1000)*0.395*1,IF(AE9>8,"",IF(AE9<8,""))) | AH9: =IF(AE9=10,AA9*AB9*AC9*AD9*(AE9/1000)*0.617*1,IF(AE9>10,"",IF(AE9<10,""))) | AI9: =IF(AE9=12,AA9*AB9*AC9*AD9*(AE9/1000)*0.888*1,IF(AE9>12,"",IF(AE9<12,""))) | AJ9: =IF(AE9=16,AA9*AB9*AC9*AD9*(AE9/1000)*1.578*1,IF(AE9>16,"",IF(AE9<16,""))) | AK9: =IF(AE9=20,AA9*AB9*AC9*AD9*(AE9/1000)*2.466*1,IF(AE9>20,"",IF(AE9<20,""))) | AL9: =IF(AE9=25,AA9*AB9*AC9*AD9*(AE9/1000)*3.853*1,IF(AE9>25,"",IF(AE9<25,""))) | AM9: =IF(AE9=32,AA9*AB9*AC9*AD9*(AE9/1000)*6.313*1,IF(AE9>32,"",IF(AE9<32,""))) | AO9: A | AP9: =SUM(R9:Y9)+SUM(AN9) -> 110.46 | AQ9: =SUM(AF9:AM9) -> 0 | AS9: varão em U (abas até à face oposta); recobrimento 5 cm (ES0101 pormenor tipo de sapatas) | AT9: Calculado
K10: AS sup xx Ø16//0.125 | L10: =$E$7-2*0.05 -> 2.7 | M10: 0.125 | N10: =$C$7 -> 1 | O10: =CEILING(L10/M10,1)+1 -> 23 | P10: 16 | Q10: =$D$7-2*0.05+2*($F$7-2*0.05) -> 3.1 | R10: =IF(P10=6,N10*O10*Q10*0.222*1,IF(P10>6,"",IF(P10<6,""))) | S10: =IF(P10=8,N10*O10*Q10*0.395*1,IF(P10>8,"",IF(P10<8,""))) | T10: =IF(P10=10,N10*O10*Q10*0.617*1,IF(P10>10,"",IF(P10<10,""))) | U10: =IF(P10=12,N10*O10*Q10*0.888*1,IF(P10>12,"",IF(P10<12,""))) | V10: =IF(P10=16,N10*O10*Q10*1.578*1,IF(P10>16,"",IF(P10<16,""))) -> 112.5114 | W10: =IF(P10=20,N10*O10*Q10*2.466*1,IF(P10>20,"",IF(P10<20,""))) | X10: =IF(P10=25,N10*O10*Q10*3.853*1,IF(P10>25,"",IF(P10<25,""))) | Y10: =IF(P10=32,N10*O10*Q10*6.313*1,IF(P10>32,"",IF(P10<32,""))) | AA10: =IF(AC10>0,N10,"") | AB10: =IF(AC10>0,O10,"") | AE10: =IF(AC10>0,P10,"") | AF10: =IF(AE10=6,AA10*AB10*AC10*AD10*(AE10/1000)*0.222*1,IF(AE10>6,"",IF(AE10<6,""))) | AG10: =IF(AE10=8,AA10*AB10*AC10*AD10*(AE10/1000)*0.395*1,IF(AE10>8,"",IF(AE10<8,""))) | AH10: =IF(AE10=10,AA10*AB10*AC10*AD10*(AE10/1000)*0.617*1,IF(AE10>10,"",IF(AE10<10,""))) | AI10: =IF(AE10=12,AA10*AB10*AC10*AD10*(AE10/1000)*0.888*1,IF(AE10>12,"",IF(AE10<12,""))) | AJ10: =IF(AE10=16,AA10*AB10*AC10*AD10*(AE10/1000)*1.578*1,IF(AE10>16,"",IF(AE10<16,""))) | AK10: =IF(AE10=20,AA10*AB10*AC10*AD10*(AE10/1000)*2.466*1,IF(AE10>20,"",IF(AE10<20,""))) | AL10: =IF(AE10=25,AA10*AB10*AC10*AD10*(AE10/1000)*3.853*1,IF(AE10>25,"",IF(AE10<25,""))) | AM10: =IF(AE10=32,AA10*AB10*AC10*AD10*(AE10/1000)*6.313*1,IF(AE10>32,"",IF(AE10<32,""))) | AO10: A | AP10: =SUM(R10:Y10)+SUM(AN10) -> 112.5114 | AQ10: =SUM(AF10:AM10) -> 0 | AS10: varão em U (abas até à face oposta); recobrimento 5 cm (ES0101 pormenor tipo de sapatas) | AT10: Calculado
K11: AS sup yy Ø16//0.125 | L11: =$D$7-2*0.05 -> 2.3 | M11: 0.125 | N11: =$C$7 -> 1 | O11: =CEILING(L11/M11,1)+1 -> 20 | P11: 16 | Q11: =$E$7-2*0.05+2*($F$7-2*0.05) -> 3.5 | R11: =IF(P11=6,N11*O11*Q11*0.222*1,IF(P11>6,"",IF(P11<6,""))) | S11: =IF(P11=8,N11*O11*Q11*0.395*1,IF(P11>8,"",IF(P11<8,""))) | T11: =IF(P11=10,N11*O11*Q11*0.617*1,IF(P11>10,"",IF(P11<10,""))) | U11: =IF(P11=12,N11*O11*Q11*0.888*1,IF(P11>12,"",IF(P11<12,""))) | V11: =IF(P11=16,N11*O11*Q11*1.578*1,IF(P11>16,"",IF(P11<16,""))) -> 110.46 | W11: =IF(P11=20,N11*O11*Q11*2.466*1,IF(P11>20,"",IF(P11<20,""))) | X11: =IF(P11=25,N11*O11*Q11*3.853*1,IF(P11>25,"",IF(P11<25,""))) | Y11: =IF(P11=32,N11*O11*Q11*6.313*1,IF(P11>32,"",IF(P11<32,""))) | AA11: =IF(AC11>0,N11,"") | AB11: =IF(AC11>0,O11,"") | AE11: =IF(AC11>0,P11,"") | AF11: =IF(AE11=6,AA11*AB11*AC11*AD11*(AE11/1000)*0.222*1,IF(AE11>6,"",IF(AE11<6,""))) | AG11: =IF(AE11=8,AA11*AB11*AC11*AD11*(AE11/1000)*0.395*1,IF(AE11>8,"",IF(AE11<8,""))) | AH11: =IF(AE11=10,AA11*AB11*AC11*AD11*(AE11/1000)*0.617*1,IF(AE11>10,"",IF(AE11<10,""))) | AI11: =IF(AE11=12,AA11*AB11*AC11*AD11*(AE11/1000)*0.888*1,IF(AE11>12,"",IF(AE11<12,""))) | AJ11: =IF(AE11=16,AA11*AB11*AC11*AD11*(AE11/1000)*1.578*1,IF(AE11>16,"",IF(AE11<16,""))) | AK11: =IF(AE11=20,AA11*AB11*AC11*AD11*(AE11/1000)*2.466*1,IF(AE11>20,"",IF(AE11<20,""))) | AL11: =IF(AE11=25,AA11*AB11*AC11*AD11*(AE11/1000)*3.853*1,IF(AE11>25,"",IF(AE11<25,""))) | AM11: =IF(AE11=32,AA11*AB11*AC11*AD11*(AE11/1000)*6.313*1,IF(AE11>32,"",IF(AE11<32,""))) | AO11: A | AP11: =SUM(R11:Y11)+SUM(AN11) -> 110.46 | AQ11: =SUM(AF11:AM11) -> 0 | AS11: varão em U (abas até à face oposta); recobrimento 5 cm (ES0101 pormenor tipo de sapatas) | AT11: Calculado
K12: AS vd 4Ø16 (cintas perimetrais) | N12: =$C$7 -> 1 | O12: 4 | P12: 16 | Q12: =2*($D$7+$E$7)-8*0.05 -> 10 | R12: =IF(P12=6,N12*O12*Q12*0.222*1,IF(P12>6,"",IF(P12<6,""))) | S12: =IF(P12=8,N12*O12*Q12*0.395*1,IF(P12>8,"",IF(P12<8,""))) | T12: =IF(P12=10,N12*O12*Q12*0.617*1,IF(P12>10,"",IF(P12<10,""))) | U12: =IF(P12=12,N12*O12*Q12*0.888*1,IF(P12>12,"",IF(P12<12,""))) | V12: =IF(P12=16,N12*O12*Q12*1.578*1,IF(P12>16,"",IF(P12<16,""))) -> 63.12 | W12: =IF(P12=20,N12*O12*Q12*2.466*1,IF(P12>20,"",IF(P12<20,""))) | X12: =IF(P12=25,N12*O12*Q12*3.853*1,IF(P12>25,"",IF(P12<25,""))) | Y12: =IF(P12=32,N12*O12*Q12*6.313*1,IF(P12>32,"",IF(P12<32,""))) | AA12: =IF(AC12>0,N12,"") -> 1 | AB12: =IF(AC12>0,O12,"") -> 4 | AC12: 1 | AD12: 50 | AE12: =IF(AC12>0,P12,"") -> 16 | AF12: =IF(AE12=6,AA12*AB12*AC12*AD12*(AE12/1000)*0.222*1,IF(AE12>6,"",IF(AE12<6,""))) | AG12: =IF(AE12=8,AA12*AB12*AC12*AD12*(AE12/1000)*0.395*1,IF(AE12>8,"",IF(AE12<8,""))) | AH12: =IF(AE12=10,AA12*AB12*AC12*AD12*(AE12/1000)*0.617*1,IF(AE12>10,"",IF(AE12<10,""))) | AI12: =IF(AE12=12,AA12*AB12*AC12*AD12*(AE12/1000)*0.888*1,IF(AE12>12,"",IF(AE12<12,""))) | AJ12: =IF(AE12=16,AA12*AB12*AC12*AD12*(AE12/1000)*1.578*1,IF(AE12>16,"",IF(AE12<16,""))) -> 5.0496 | AK12: =IF(AE12=20,AA12*AB12*AC12*AD12*(AE12/1000)*2.466*1,IF(AE12>20,"",IF(AE12<20,""))) | AL12: =IF(AE12=25,AA12*AB12*AC12*AD12*(AE12/1000)*3.853*1,IF(AE12>25,"",IF(AE12<25,""))) | AM12: =IF(AE12=32,AA12*AB12*AC12*AD12*(AE12/1000)*6.313*1,IF(AE12>32,"",IF(AE12<32,""))) | AO12: A | AP12: =SUM(R12:Y12)+SUM(AN12) -> 63.12 | AQ12: =SUM(AF12:AM12) -> 5.0496 | AS12: interpretado: ASvd = cintas horizontais no contorno; 1 emenda 50Ø por cinta | AT12: Interpretado
